Workbook

Sheet DANH MỤC
A1: DANH MỤC CHECKLIST KIỂM SOÁT CHẤT LƯỢNG THI CÔNG
A2: Công trình:
A3: Địa điểm:
A5: TT | B5: Nội dung | C5: Biểu mẫu
B6: Cọc
B7: Ép cọc bê tông
A8: 1 | B8: Đúc cọc tại hiện trường | C8: BM1
A9: 2 | B9: Cọc bê tông đúc sẵn | C9: BM2
A10: 3 | B10: Ép cọc | C10: BM3
A11: 4 | B11: Cắt đầu cọc ly tâm | C11: BM4
A12: 5 | B12: Phá đầu cọc bê tông | C12: BM5
B13: Cọc khoan nhồi
A14: 1 | B14: Định vị tim cọc, hạ ống casing | C14: BM06
A15: 2 | B15: Công tác khoan tạo lỗ | C15: BM07
A16: 3 | B16: Kiểm tra nghiệm thu lồng thép | C16: BM08
A17: 4 | B17: Kiểm tra công tác vét lắng, dung dịch giữ thành hố khoan | C17: BM09
A18: 5 | B18: Kiểm tra công tác hạ lồng thép | C18: BM10
A19: 6 | B19: Kiểm tra công tác hạ ống đổ, thổi rửa lần 2 | C19: BM11
A20: 7 | B20: Kiểm tra dung dịch giữ thành hố khoan, công tác đổ bê tông | C20: BM12
A21: 8 | B21: Công tác hạ kingpost | C21: BM13
A22: 9 | B22: Công tác lấp đất đầu cọc có kingpost | C22: BM14
B23: Móng
A24: 1 | B24: Đào đất móng | C24: BM15
A25: 2 | B25: Gia công lắp dựng cốt thép móng, cổ cột | C25: BM16
A26: 3 | B26: Gia công lắp dựng ván khuôn móng | C26: BM17
A27: 4 | B27: Đổ bê tông móng | C27: BM18
A28: 5 | B28: Lấp đất móng | C28: BM19
B29: Phần thân thô
A30: 1 | B30: Gia công lắp dựng cốt thép cột, vách | C30: BM20
A31: 2 | B31: Gia công lắp dựng ván khuôn cột, vách | C31: BM21
A32: 3 | B32: Công tác đổ bê tông cột, vách | C32: BM22
A33: 4 | B33: Gia công lắp dựng ván khuôn dầm sàn | C33: BM23
A34: 5 | B34: Gia công lắp dựng cốt thép dầm sàn | C34: BM24
A35: 6 | B35: Bê tông dầm sàn | C35: BM25
B36: Phần hoàn thiện
A37: 1 | B37: Xây tường | C37: BM26
A38: 2 | B38: Lanh tô, trụ tường | C38: BM27
A39: 3 | B39: Tô/Trát | C39: BM28
A40: 4 | B40: Chống thấm nền vệ sinh | C40: BM29
A41: 5 | B41: Láng nền sàn | C41: BM30
...

Sheet BM1  
A2: CÔNG TY TNHH THƯƠNG MẠI VÀ DỊCH VỤ XÂY DỰNG NHÀ CỦA MÌNH AC | E2: CỘNG HÒA XÃ HỘI CHỦ NGHĨA VIỆT NAM
E3: Độc Lập - Tự Do - Hạnh Phúc
E4: Ngày…..tháng…..năm 202…..
A5: CHECKLIST KIỂM TRA | I5: Ấn để trở về sheet " Danh mục"
A6: Công trình: | C6: =+'DANH MỤC'!A2 -> Công trình:
C7: =+'DANH MỤC'!A3 -> Địa điểm:
C8: ="Công tác"&": "&'DANH MỤC'!B8 -> Công tác: Đúc cọc tại hiện trường
A10: TT | B10: Công tác | C10: Công việc kiểm tra: | D10: Phương pháp kiểm tra | E10: Mức cho phép | F10: Đánh giá | H10: Ghi chú
F11: Đạt | G11: K.Đạt
A12: 1 | B12: Công tác thép | C12: Chủng loại, đường kính | D12: ĐK đo bằng thước kẹp | E12: Chủng loại theo HĐ (VL đã được nghiệm thu đầu vào) | H12: TCVN 4453:1995
C13: Chiều dài thép | D13: Đo bằng thước | H13: TCVN 4453:1995
C14: Định vị các thanh thép | D14: Đo bằng thước | H14: TCVN 4453:1995
C15: Vị trí mối nối | D15: Đo bằng thước | E15: Theo bản Shopdrawing | H15: TC chưa quy định
C16: Chiều dài mối nối | D16: Đo bằng thước | E16: Theo quy định trong HSTK | H16: Dầm tường ≥40D KC khác ≥30D
C17: Chiều dày lớp bê tông bảo vệ | D17: Đo bằng thước | E17: Tối thiểu 4cm | H17: TCVN 5574:2012
C18: Công tác vệ sinh cốt thép | D18: Mắt thường | E18: Không bám bẩn
C19: Bản mã đầu cọc | D19: Đo bằng thước | E19: Theo TK
C20: Mũi cọc | D20: Đo bằng thước | E20: Theo TK
A21: 2 | B21: Công tác ván khuôn | C21: Kích thước hình học | D21: Đo bằng thước | E21: Sai lệch +/-3 mm | H21: TCVN 4453:1995
C22: Độ chắc chắn và kín khít của ván khuôn. | D22: Mắt thường | E22: Sai lệch +2 mm | H22: TCVN 4453:1995
C23: Bề mặt ván khuôn | D23: Mắt thường | E23: Sạch, phẳng, không bám dính. Sai lệch +/-1mm/m | H23: TCVN 4453:1995
A24: 3 | B24: Công tác đổ bê tông cọc | C24: Cấp phối bêtông | D24: Kiểm tra thiết kế cấp phối | E24: Mác yêu cầu cao hơn hoặc bằng TK
C25: Công tác đầm | D25: Mắt thường | E25: Nước XM nổi đều trên bề mặt thì dừng
C26: Kích thước hình học | D26: Đo bằng thước | E26: Sai lệch +/-1mm/m | H26: TCVN 4453:1995
C27: Bảo dưỡng | D27: Theo dõi | E27: 3 ngày
A28: 4 | B28: Chất lượng BT cọc | C28: Kích thước hình học | D28: Đo bằng thước | E28: Sai lệch ≤ 2cm Bề mặt +/-1mm/m
C29: Tình trạng bề mặt (nứt, rỗ v.v...) | D29: Mắt thường | E29: Bề rộng ≤ 0,2mm | H29: TCVN 5574:2018
C30: Cường độ thí nghiệm bê tông | D30: Kết quả thí nghiệm | H30: TCVN 3118:1993
B31: Ghi chú: Chi tiết các chỉ tiêu xem tiêu chuẩn kỹ thuật quy định tại cột ghi chú
A32: GHI CHÚ CHUNG:
A45: CHỦ ĐẦU TƯ TRỢ LÝ XÂY NHÀ ĐƠN VỊ THI CÔNG

Sheet BM2 
A2: CÔNG TY TNHH THƯƠNG MẠI VÀ DỊCH VỤ XÂY DỰNG NHÀ CỦA MÌNH AC | E2: CỘNG HÒA XÃ HỘI CHỦ NGHĨA VIỆT NAM
E3: Độc Lập - Tự Do - Hạnh Phúc
E4: Ngày…..tháng…..năm 202…..
A5: CHECKLIST KIỂM TRA | I5: Ấn để trở về sheet " Danh mục"
A6: Công trình: | C6: =+'DANH MỤC'!A2 -> Công trình:
C7: =+'DANH MỤC'!A3 -> Địa điểm:
C8: ="Công tác"&": "&'DANH MỤC'!B9 -> Công tác: Cọc bê tông đúc sẵn
A10: TT | B10: Công tác | C10: Công việc kiểm tra: | D10: Phương pháp kiểm tra | E10: Mức cho phép | F10: Đánh giá | H10: Ghi chú
F11: Đạt | G11: K.Đạt
A12: 1 | B12: Cọc đúc sẵn | C12: Kết quả nén mẫu bê tông | D12: Nén 03 mẫu BT hình lập phương kích thước 150x150x150 mm | H12: TCVN 3118:1993
C13: Chiều dài cọc | D13: Đo bằng thước | H13: TCVN 286:2003
C14: Kích thước, đường kính cọc | D14: Đo bằng thước | E14: +5mm | H14: TCVN 286:2003
C15: Chiều dài mũi cọc | D15: Đo bằng thước | H15: TCVN 286:2003
C16: Độ lệch mũi cọc khỏi tâm cọc | D16: Mắt thường Đo bằng thước | E16: +10mm | H16: TCVN 286:2003
C17: Khoảng cách từ tâm móc treo đến đoạn đầu cọc ( nếu có) | D17: Đo bằng thước | H17: TCVN 286:2003
C18: Độ lệch của móc treo so với trục cọc | H18: TCVN 286:2003
C19: Độ cong của cọc ( lồi hoặc lõm) | E19: +10mm | H19: TCVN 286:2003
A20: 3 | C20: Độ võng của đoạn cọc | D20: Máy laser | E20: 1/100 chiều dài đốt cọc | H20: TCVN 286:2003
C21: Bề mặt cọc | D21: Mắt thường | E21: - Màu sắc cọc đồng đều, diện tích lẹm, sứt góc, rỗ tổ ong không quá 5% bề mặt, không tập trung. | H21: TCVN 286:2003
C22: Vết nứt | D22: Thước đo chuyên dụng. | H22: TCVN 286:2003
B23: Ghi chú: Chi tiết các chỉ tiêu xem tiêu chuẩn kỹ thuật quy định tại cột ghi chú
A24: GHI CHÚ CHUNG:
A37: CHỦ ĐẦU TƯ TRỢ LÝ XÂY NHÀ ĐƠN VỊ THI CÔNG

Sheet BM3 
A2: CÔNG TY TNHH THƯƠNG MẠI VÀ DỊCH VỤ XÂY DỰNG NHÀ CỦA MÌNH AC | E2: CỘNG HÒA XÃ HỘI CHỦ NGHĨA VIỆT NAM
E3: Độc Lập - Tự Do - Hạnh Phúc
E4: Ngày…..tháng…..năm 202…..
A5: CHECKLIST KIỂM TRA | I5: Ấn để trở về sheet " Danh mục"
A6: Công trình: | C6: =+'DANH MỤC'!A2 -> Công trình:
C7: =+'DANH MỤC'!A3 -> Địa điểm:
C8: ="Công tác"&": "&'DANH MỤC'!B10 -> Công tác: Ép cọc
A10: TT | B10: Công tác | C10: Công việc kiểm tra: | D10: Phương pháp kiểm tra | E10: Mức cho phép | F10: Đánh giá | H10: Ghi chú
F11: Đạt | G11: K.Đạt
A12: 1 | B12: Công tác ép cọc | C12: Định vị tim cọc | D12: Máy toàn đạc | E12: ≤ 0,2D ( D đường kính cọc biên) ≤ 0,3D ( D đường kính cọc giữa) | H12: TCVN 9394:2012
C13: Chất lượng cọc. | D13: Bằng mắt | H13: TCVN 286:2003
C14: Tổ hợp các đoạn cọc | D14: Đo bằng thước | E14: Theo Shopdrawing được phê duyệt. | H14: TCVN 9394:2012
C15: Vệ sinh mũi cọc | D15: Bằng mắt | E15: Mũi cọc phải vệ sinh sạch sẽ trước khi hàn.
C16: Kích thước bản mã hàn cọc | D16: Đo bằng thước | E16: Theo Shopdrawing được phê duyệt. | H16: TCVN 9394:2012
C17: Độ thẳng đứng cọc | D17: Thước ni vô | E17: Độ nghiêng cho phép 1/100 mỗi phương | H17: TCVN 9394:2012
C18: Đường hàn mặt bích nối cọc. | D18: Bằng mắt | E18: - Chiều cao, chiều rộng mối hàn đồng đều, hàn ngấu, không bị khuyết tật. | H18: TCVN 9394:2012
C19: Máy ép cọc | D19: Tải trọng máy + đối trọng. | H19: TCVN 9394:2012
C20: Điều kiện dừng ép | D20: Đo bằng thước Mắt thường | H20: TCVN 9394:2012
B22: Ghi chú: Chi tiết các chỉ tiêu xem tiêu chuẩn kỹ thuật quy định tại cột ghi chú
A23: GHI CHÚ CHUNG:
A36: CHỦ ĐẦU TƯ TRỢ LÝ XÂY NHÀ ĐƠN VỊ THI CÔNG

Sheet BM4 
A2: CÔNG TY TNHH THƯƠNG MẠI VÀ DỊCH VỤ XÂY DỰNG NHÀ CỦA MÌNH AC | E2: CỘNG HÒA XÃ HỘI CHỦ NGHĨA VIỆT NAM
E3: Độc Lập - Tự Do - Hạnh Phúc
E4: Ngày…..tháng…..năm 202…..
A5: CHECKLIST KIỂM TRA | I5: Ấn để trở về sheet " Danh mục"
A6: Công trình: | C6: =+'DANH MỤC'!A2 -> Công trình:
C7: =+'DANH MỤC'!A3 -> Địa điểm:
C8: ="Công tác"&": "&'DANH MỤC'!B11 -> Công tác: Cắt đầu cọc ly tâm
A10: TT | B10: Công tác | C10: Công việc kiểm tra: | D10: Phương pháp kiểm tra | E10: Mức cho phép | F10: Đánh giá | H10: Ghi chú
F11: Đạt | G11: K.Đạt
A12: 1 | B12: Công tác cắt đầu cọc | C12: Định vị vị trí cắt cọc | D12: Máy toàn đạc | E12: Theo Shopdrawing được phê duyệt.
C13: Máy cắt đầu cọc | D13: Tem kiểm định an toàn | E13: Có bộ phận che chắn lưỡi cắt đảm bảo công tác An toàn.
C14: Bề mặt cọc sau khi cắt. | D14: Bằng mắt thường | E14: Bề mặt cọc phẳng nhẵn, không sứt vỡ.
C15: Dọn vệ sinh đầu cọc | D15: Bằng mắt thường | E15: Đầu cọc thừa sau khi cắt xong phải chuyển ra ngoài công trường.
B17: Ghi chú: Chi tiết các chỉ tiêu xem tiêu chuẩn kỹ thuật quy định tại cột ghi chú
A18: GHI CHÚ CHUNG:
A31: CHỦ ĐẦU TƯ TRỢ LÝ XÂY NHÀ ĐƠN VỊ THI CÔNG

Sheet BM5 
A2: CÔNG TY TNHH THƯƠNG MẠI VÀ DỊCH VỤ XÂY DỰNG NHÀ CỦA MÌNH AC | E2: CỘNG HÒA XÃ HỘI CHỦ NGHĨA VIỆT NAM
E3: Độc Lập - Tự Do - Hạnh Phúc
E4: Ngày…..tháng…..năm 202…..
A5: CHECKLIST KIỂM TRA | I5: Ấn để trở về sheet " Danh mục"
A6: Công trình: | C6: =+'DANH MỤC'!A2 -> Công trình:
C7: =+'DANH MỤC'!A3 -> Địa điểm:
C8: ="Công tác"&": "&'DANH MỤC'!B12 -> Công tác: Phá đầu cọc bê tông
A10: TT | B10: Công tác | C10: Công việc kiểm tra: | D10: Phương pháp kiểm tra | E10: Mức cho phép | F10: Đánh giá | H10: Ghi chú
F11: Đạt | G11: K.Đạt
A12: 1 | B12: Công tác phá đầu cọc | C12: Cao độ đầu cọc hiện trạng trước khi phá bê tông. | D12: Máy toàn đạc | E12: Theo thực tế
C13: Định vị cao độ đầu cọc | D13: Máy toàn đạc | E13: Theo Shopdrawing được phê duyệt.
C14: Bề mặt cọc sau khi phá bê tông | D14: Bằng mắt thường | E14: Bề mặt cọc phẳng nhẵn, không sứt vỡ.
C15: Chiều dài phá bê tông đầu cọc | D15: Đo bằng thước | E15: Đo thực tế
C16: Cốt thép đầu cọc Chủng loại, đường kính, số lượng thép chủ. Vị trí chiều dài thanh thép đầu cọc | D16: Đo bằng thước Bằng mắt thường. | E16: Theo thiết kế. ( Thường ≥ 30D )
C17: Dọn vệ sinh bê tông đầu cọc | D17: Bằng mắt thường | E17: Bê tông đầu cọc sau khi phá phải chuyển ra ngoài công trường.
B18: Ghi chú: Chi tiết các chỉ tiêu xem tiêu chuẩn kỹ thuật quy định tại cột ghi chú
A19: GHI CHÚ CHUNG:
A32: CHỦ ĐẦU TƯ TRỢ LÝ XÂY NHÀ ĐƠN VỊ THI CÔNG

Sheet BM06 
A2: CÔNG TY TNHH THƯƠNG MẠI VÀ DỊCH VỤ XÂY DỰNG NHÀ CỦA MÌNH AC | E2: CỘNG HÒA XÃ HỘI CHỦ NGHĨA VIỆT NAM
E3: Độc Lập - Tự Do - Hạnh Phúc
E4: Ngày…..tháng…..năm 202…..
A5: CHECKLIST KIỂM TRA | I5: Ấn để trở về sheet " Danh mục"
A6: Công trình: | C6: =+'DANH MỤC'!A2 -> Công trình:
C7: =+'DANH MỤC'!A3 -> Địa điểm:
C8: ="Công tác"&": "&'DANH MỤC'!B14 -> Công tác: Định vị tim cọc, hạ ống casing
A10: TT | B10: Công tác | C10: Công việc kiểm tra: | D10: Phương pháp kiểm tra | E10: Mức cho phép | F10: Đánh giá | H10: Ghi chú
F11: Đạt | G11: K.Đạt
A12: 1 | B12: Công tác thép | C12: Kiểm tra cao độ mặt đất tự nhiên | D12: Máy toàn đạc Máy thủy bình
C13: Định vị tim cọc ( Miệng casing) | D13: Máy toàn đạc | E13: 1. D≤100cm: a. Cọc biên: D/6 nhưng ≤10cm b. Cọc giữa: D/4 nhưng ≤15cm 2. D>100cm a. Cọc biên: 10+0.01H b. Cọc giữa: 15+0.01H (D: đường kính cọc, H: chiều cao từ mặt đất thực tế đến điểm cắt cọc) | H13: TCVN 9395-2012
C14: Hạ ống casing | D14: Máy toàn đạc | E14: BPTC được phê duyệt
C15: Kiểm tra cao độ đỉnh casing | D15: Máy toàn đạc | E15: Cao hơn mđtn tối thiểu là 30cm | H15: TCVN 9395-2012
C16: Độ thẳng đứng casing | D16: Máy toàn đạc | H16: TCVN 9395-2012
B17: Ghi chú: Chi tiết các chỉ tiêu xem tiêu chuẩn kỹ thuật quy định tại cột ghi chú
A18: GHI CHÚ CHUNG:
A31: CHỦ ĐẦU TƯ TRỢ LÝ XÂY NHÀ ĐƠN VỊ THI CÔNG

Sheet BM07 
A2: CÔNG TY TNHH THƯƠNG MẠI VÀ DỊCH VỤ XÂY DỰNG NHÀ CỦA MÌNH AC | E2: CỘNG HÒA XÃ HỘI CHỦ NGHĨA VIỆT NAM
E3: Độc Lập - Tự Do - Hạnh Phúc
E4: Ngày…..tháng…..năm 202…..
A5: CHECKLIST KIỂM TRA | I5: Ấn để trở về sheet " Danh mục"
A6: Công trình: | C6: =+'DANH MỤC'!A2 -> Công trình:
C7: =+'DANH MỤC'!A3 -> Địa điểm:
C8: ="Công tác"&": "&'DANH MỤC'!B15 -> Công tác: Công tác khoan tạo lỗ
A10: TT | B10: Công tác | C10: Công việc kiểm tra: | D10: Phương pháp kiểm tra | E10: Mức cho phép | F10: Đánh giá | H10: Ghi chú
F11: Đạt | G11: K.Đạt
A12: 1 | B12: Công tác khoan tạo lỗ | C12: Kiểm tra đường kính gàu khoan | D12: Thước mét | H12: TCVN 9395-2012
C13: Kiểm tra thiết bị khoan: độ thẳng đứng cần khoan. | D13: Máy toàn đạc Dây dọi | H13: TCVN 9395-2012
C14: Kiểm tra dung dịch trước khi khoan( PH, độ nhớt, tỉ trọng, hàm lượng cát…) | D14: Dụng cụ chuyên dụng | E14: 1. Khối lượng riêng: 1 ÷ 1.04g/ml 2. Độ nhớt: 32÷45 giây 3. Hàm lượng cát:<1% 4. Độ PH: 8-10.5 Hoặc theo quy định của từng nhà sản xuất | H14: TCVN 9395-2012
C15: Kiểm tra chiều sâu các lớp địa chất cọc | E15: BPTC được phê duyệt
C16: Kiểm tra chiều sâu chạm sỏi đá. | D16: Thước dây không dãn, quả dọi tiêu chuẩn | E16: Theo hồ sơ thiết kế quy định
C17: Kiểm tra dung dịch giữ thành trong lúc khoan. | D17: Dụng cụ chuyên dụng | E17: 1. Khối lượng riêng: 1 ÷ 1.04g/ml 2. Độ nhớt: 32÷45 giây 3. Hàm lượng cát:<1% 4. Độ PH: 8-10.5 Hoặc theo quy định của từng nhà sản xuất | H17: TCVN 9395-2012
C18: Kiểm tra chiều sâu kết thúc khoan tạo lỗ. | D18: Thước dây không dãn, quả dọi tiêu chuẩn | E18: ± 10 cm | H18: TCVN 9395-2012
C19: Kiểm tra độ thẳng đứng của hố khoan | D19: Koden | E19: Theo yêu cầu của thiết kế, nếu thiết kế không quy định lấy giá trị: ≤ 1% | H19: TCVN 9395-2012
B20: Ghi chú: Chi tiết các chỉ tiêu xem tiêu chuẩn kỹ thuật quy định tại cột ghi chú
A21: GHI CHÚ CHUNG:
A34: CHỦ ĐẦU TƯ TRỢ LÝ XÂY NHÀ ĐƠN VỊ THI CÔNG

Sheet BM08  
A2: CÔNG TY TNHH THƯƠNG MẠI VÀ DỊCH VỤ XÂY DỰNG NHÀ CỦA MÌNH AC | E2: CỘNG HÒA XÃ HỘI CHỦ NGHĨA VIỆT NAM
E3: Độc Lập - Tự Do - Hạnh Phúc
E4: Ngày…..tháng…..năm 202…..
A5: CHECKLIST KIỂM TRA | I5: Ấn để trở về sheet " Danh mục"
A6: Công trình: | C6: =+'DANH MỤC'!A2 -> Công trình:
C7: =+'DANH MỤC'!A3 -> Địa điểm:
C8: ="Công tác"&": "&'DANH MỤC'!B16 -> Công tác: Kiểm tra nghiệm thu lồng thép
A10: TT | B10: Công tác | C10: Công việc kiểm tra: | D10: Phương pháp kiểm tra | E10: Mức cho phép | F10: Đánh giá | H10: Ghi chú
F11: Đạt | G11: K.Đạt
A12: 1 | B12: Công tác kiểm tra lồng thép | C12: Số lượng, đường kính, kích thước thép chủ, thép đai | D12: Thước dây, thước mét | E12: 1. Cự ly giữa các cốt thép chủ: ± 10 mm 2. Cự ly cốt đai hoặc cốt lò xo: ± 20 mm 3. Đường kính lồng thép: ± 10mm 4. Độ dài lồng thép : ± 50 mm | H12: TCVN 9395-2012
C13: Kiểm tra số lượng, đường kính và hàn nối ống siêu âm | D13: Thước kẹp, bẳng trực quan | E13: Biện pháp thi công phê duyệt
C14: Kiểm tra kích thước, chủng loại, số lượng con kê | D14: Bằng trực quan | E14: Biện pháp thi công phê duyệt
B15: Ghi chú: Chi tiết các chỉ tiêu xem tiêu chuẩn kỹ thuật quy định tại cột ghi chú
A16: GHI CHÚ CHUNG:
A29: CHỦ ĐẦU TƯ TRỢ LÝ XÂY NHÀ ĐƠN VỊ THI CÔNG

Sheet BM09 
A2: CÔNG TY TNHH THƯƠNG MẠI VÀ DỊCH VỤ XÂY DỰNG NHÀ CỦA MÌNH AC | E2: CỘNG HÒA XÃ HỘI CHỦ NGHĨA VIỆT NAM
E3: Độc Lập - Tự Do - Hạnh Phúc
E4: Ngày…..tháng…..năm 202…..
A5: CHECKLIST KIỂM TRA | I5: Ấn để trở về sheet " Danh mục"
A6: Công trình: | C6: =+'DANH MỤC'!A2 -> Công trình:
C7: =+'DANH MỤC'!A3 -> Địa điểm:
C8: ="Công tác"&": "&'DANH MỤC'!B17 -> Công tác: Kiểm tra công tác vét lắng, dung dịch giữ thành hố khoan
A10: TT | B10: Công tác | C10: Công việc kiểm tra: | D10: Phương pháp kiểm tra | E10: Mức cho phép | F10: Đánh giá | H10: Ghi chú
F11: Đạt | G11: K.Đạt
A12: 1 | B12: Công tác vét lắng, dung dịch giữ thành hố khoan | C12: Kiểm tra công tác vét lắng lần 1 | D12: Dùng gầu vét, kiểm tra bằng thước dây không dãn và quả dọi | E12: Tối thiểu bằng chiều sâu kết thúc khoan Kiểm tra cao độ Casing sau khi vét lắng
C13: Kiểm tra dung dịch giữ thành trước lúc hạ lồng ( Bentonite) | D13: Dụng cụ chuyên dụng | E13: 1. Khối lượng riêng: 1.05 ÷ 1.15g/ml 2. Độ nhớt: 18÷45 giây 3. Hàm lượng cát:<6% 4. Độ PH: 7-9 Hoặc theo quy định của từng nhà sản xuất | H13: TCVN 9395-2012
C14: Kiểm tra dung dịch giữ thành trước lúc hạ lồng ( Polyme) | D14: Dụng cụ chuyên dụng | E14: 1. Khối lượng riêng: 1 ÷ 1.04g/ml 2. Độ nhớt: 32÷45 giây 3. Hàm lượng cát:<1% 4. Độ PH: 8-10.5 Hoặc theo quy định của từng nhà sản xuất | H14: TCVN 9395-2012
B16: Ghi chú: Chi tiết các chỉ tiêu xem tiêu chuẩn kỹ thuật quy định tại cột ghi chú
A17: GHI CHÚ CHUNG:
A30: CHỦ ĐẦU TƯ TRỢ LÝ XÂY NHÀ ĐƠN VỊ THI CÔNG

Sheet BM10 
A2: CÔNG TY TNHH THƯƠNG MẠI VÀ DỊCH VỤ XÂY DỰNG NHÀ CỦA MÌNH AC | E2: CỘNG HÒA XÃ HỘI CHỦ NGHĨA VIỆT NAM
E3: Độc Lập - Tự Do - Hạnh Phúc
E4: Ngày…..tháng…..năm 202…..
A5: CHECKLIST KIỂM TRA | I5: Ấn để trở về sheet " Danh mục"
A6: Công trình: | C6: =+'DANH MỤC'!A2 -> Công trình:
C7: =+'DANH MỤC'!A3 -> Địa điểm:
C8: ="Công tác"&": "&'DANH MỤC'!B18 -> Công tác: Kiểm tra công tác hạ lồng thép
A10: TT | B10: Công tác | C10: Công việc kiểm tra: | D10: Phương pháp kiểm tra | E10: Mức cho phép | F10: Đánh giá | H10: Ghi chú
F11: Đạt | G11: K.Đạt
A12: 1 | B12: Công tác hạ lồng thép | C12: Kiểm tra cao độ casing trước lúc hạ lồng thép | D12: Máy toàn đạc | E12: Cao hơn mđtn tối thiểu là 30cm
C13: Thời gian từ lúc vét lắng lần 2 đến thời điểm hạ lồng thép | E13: Không quá 1 giờ.
C14: Kiểm tra chất lượng mối nối lồng thép. | D14: Bằng trực quan, thước mét | E14: 1. Thép chủ: tối thiểu 3 mối buộc (tối thiểu 5 mối buộc) 2. Thép đai vị trí nối lồng: buộc 100% vào thép chủ. 3. Hàn nối lồng: chiều dài mối hàn tối thiểu 5 cm (tối thiểu hàn 03 vị trí/1 đoạn nối) | H14: TCVN 9395-2012
C15: Kiểm tra số lượng đai nối lồng | D15: Bằng trực quan | E15: BPTC được phê duyệt
C16: Kiểm tra mối hàn nối ống siêu âm (nếu có) | D16: Bơm nước thử kín | E16: BPTC được phê duyệt
C17: Độ lệch tâm ống siêu âm tại vị trí nối lồng | D17: Đo bằng thước | E17: Không quá 0.5 cm
B19: Ghi chú: Chi tiết các chỉ tiêu xem tiêu chuẩn kỹ thuật quy định tại cột ghi chú
A20: GHI CHÚ CHUNG:
A33: CHỦ ĐẦU TƯ TRỢ LÝ XÂY NHÀ ĐƠN VỊ THI CÔNG

Sheet BM11 
A2: CÔNG TY TNHH THƯƠNG MẠI VÀ DỊCH VỤ XÂY DỰNG NHÀ CỦA MÌNH AC | E2: CỘNG HÒA XÃ HỘI CHỦ NGHĨA VIỆT NAM
E3: Độc Lập - Tự Do - Hạnh Phúc
E4: Ngày…..tháng…..năm 202…..
A5: CHECKLIST KIỂM TRA | I5: Ấn để trở về sheet " Danh mục"
A6: Công trình: | C6: =+'DANH MỤC'!A2 -> Công trình:
C7: =+'DANH MỤC'!A3 -> Địa điểm:
C8: ="Công tác"&": "&'DANH MỤC'!B19 -> Công tác: Kiểm tra công tác hạ ống đổ, thổi rửa lần 2
A10: TT | B10: Công tác | C10: Công việc kiểm tra: | D10: Phương pháp kiểm tra | E10: Mức cho phép | F10: Đánh giá | H10: Ghi chú
F11: Đạt | G11: K.Đạt
A12: 1 | B12: Công tác hạ ống đổ | C12: Kiểm tra kích thước, vệ sinh và độ kín nước của ống đổ | D12: Bằng trực quan, thước mét | E12: Đường kính trong ống đổ ≥ 200 mm
C13: Kiểm tra tổ hợp ống đổ | D13: Số lượng, chiều dài ống | E13: Đáy ống đổ cách đáy cọc <= 0,3m | H13: TCVN 9395-2012
B14: Công tác thổi rửa lần 2 | C14: Kiểm tra nghiệm thu công tác thổi rửa lần 2 (trước khi đổ bê tông) | D14: Dùng khí nén thổi đẩy lắng, dùng thước dây không dãn và quả dọi kiểm tra | E14: Cốt đảm bảo đáy lắng ≤ 5 cm (kiểm tra cốt ống casing; cốt vét lắng cọc, cốt thổi rửa) | H14: TCVN 9395-2012
B15: Ghi chú: Chi tiết các chỉ tiêu xem tiêu chuẩn kỹ thuật quy định tại cột ghi chú
A16: GHI CHÚ CHUNG:
A29: CHỦ ĐẦU TƯ TRỢ LÝ XÂY NHÀ ĐƠN VỊ THI CÔNG

Sheet BM12 
A2: CÔNG TY TNHH THƯƠNG MẠI VÀ DỊCH VỤ XÂY DỰNG NHÀ CỦA MÌNH AC | E2: CỘNG HÒA XÃ HỘI CHỦ NGHĨA VIỆT NAM
E3: Độc Lập - Tự Do - Hạnh Phúc
E4: Ngày…..tháng…..năm 202…..
A5: CHECKLIST KIỂM TRA | I5: Ấn để trở về sheet " Danh mục"
A6: Công trình: | C6: =+'DANH MỤC'!A2 -> Công trình:
C7: =+'DANH MỤC'!A3 -> Địa điểm:
C8: ="Công tác"&": "&'DANH MỤC'!B20 -> Công tác: Kiểm tra dung dịch giữ thành hố khoan, công tác đổ bê tông
A10: TT | B10: Công tác | C10: Công việc kiểm tra: | D10: Phương pháp kiểm tra | E10: Mức cho phép | F10: Đánh giá | H10: Ghi chú
F11: Đạt | G11: K.Đạt
A12: 1 | B12: Kiểm tra dung dịch giữ thành hố khoan trước khi đổ bê tông | C12: Kiểm tra dung dịch giữ thành trước khi đổ bê tông | D12: Dụng cụ chuyên dụng | E12: 1. Khối lượng riêng: 1 ÷ 1.04g/ml 2. Độ nhớt: 32÷45 giây 3. Hàm lượng cát:<1% 4. Độ PH: 8-10.5 Hoặc theo quy định của từng nhà sản xuất | H12: TCVN 9395-2012
B13: Công tác đổ bê tông | C13: Độ sụt bê tông | D13: Côn rút sụt | E13: Độ sụt bê tông được duy trì 3 đến 4h: - Cọc D<=1000 duy trì 3h - Cọc D>=1200, cọc có cây sinh duy trì 4h | H13: TCVN 9395-2012
C14: Thời gian từ lúc trộn bê tông đến thời điểm đổ | E14: <=1,5h | H14: TCVN 4453-1995
C15: Độ dâng bê tông | D15: Thước dây | E15: BPTC phê duyệt
C16: Chiều dài ống đổ ngậm trong bê tông | D16: Thước dây | E16: >= 5,0 m | H16: TCVN 9395-2012
C17: Kiểm tra thể tích bê tông thực tế và so với kích thước lỗ cọc theo lý thuyết | E17: Không quá 10% so với lý thuyết. (Nếu vượt quá 10% thì phải xem lại biện pháp giữ thành hố khoan) | H17: Thông tư 10/2019/TT-BXD
B19: Ghi chú: Chi tiết các chỉ tiêu xem tiêu chuẩn kỹ thuật quy định tại cột ghi chú
A20: GHI CHÚ CHUNG:
A33: CHỦ ĐẦU TƯ TRỢ LÝ XÂY NHÀ ĐƠN VỊ THI CÔNG

Sheet BM13 
A2: CÔNG TY TNHH THƯƠNG MẠI VÀ DỊCH VỤ XÂY DỰNG NHÀ CỦA MÌNH AC | E2: CỘNG HÒA XÃ HỘI CHỦ NGHĨA VIỆT NAM
E3: Độc Lập - Tự Do - Hạnh Phúc
E4: Ngày…..tháng…..năm 202…..
A5: CHECKLIST KIỂM TRA | I5: Ấn để trở về sheet " Danh mục"
A6: Công trình: | C6: =+'DANH MỤC'!A2 -> Công trình:
C7: =+'DANH MỤC'!A3 -> Địa điểm:
C8: ="Công tác"&": "&'DANH MỤC'!B22 -> Công tác: Công tác lấp đất đầu cọc có kingpost
A10: TT | B10: Công tác | C10: Công việc kiểm tra: | D10: Phương pháp kiểm tra | E10: Mức cho phép | F10: Đánh giá | H10: Ghi chú
F11: Đạt | G11: K.Đạt
A12: 1 | B12: Công tác lấp đất đầu cọc | C12: Kiểm tra chất lượng kingpost: mối hàn, số lượng ecu, bulong, tai | D12: Máy siêu âm | E12: BPTC được phê duyệt
C13: Kiểm tra độ bằng phẳng bàn dẫn hướng, tim bàn dẫn hướng, tiến hành hạ và cố định bàn dẫn hướng vào casing | D13: Máy toàn đạc | E13: 0.5 cm
C14: Kiểm tra phương kingpost theo thiết kế | D14: Bằng mắt thường | E14: BPTC được phê duyệt
C15: Cao độ kingpost sau khi hạ | D15: Máy thủy bình | E15: ± 1 cm | H15: TCVN 9395-2012
C16: Cố định kingpost vào bàn dẫn hướng | D16: Bằng trực quan | E16: BPTC được phê duyệt
B18: Ghi chú: Chi tiết các chỉ tiêu xem tiêu chuẩn kỹ thuật quy định tại cột ghi chú
A19: GHI CHÚ CHUNG:
A32: CHỦ ĐẦU TƯ TRỢ LÝ XÂY NHÀ ĐƠN VỊ THI CÔNG

Sheet BM14
A2: CÔNG TY TNHH THƯƠNG MẠI VÀ DỊCH VỤ XÂY DỰNG NHÀ CỦA MÌNH AC | E2: CỘNG HÒA XÃ HỘI CHỦ NGHĨA VIỆT NAM
E3: Độc Lập - Tự Do - Hạnh Phúc
E4: Ngày…..tháng…..năm 202…..
A5: CHECKLIST KIỂM TRA | I5: Ấn để trở về sheet " Danh mục"
A6: Công trình: | C6: =+'DANH MỤC'!A2 -> Công trình:
C7: =+'DANH MỤC'!A3 -> Địa điểm:
C8: ="Công tác"&": "&'DANH MỤC'!B22 -> Công tác: Công tác lấp đất đầu cọc có kingpost
A10: TT | B10: Công tác | C10: Công việc kiểm tra: | D10: Phương pháp kiểm tra | E10: Mức cho phép | F10: Đánh giá | H10: Ghi chú
F11: Đạt | G11: K.Đạt
A12: 1 | B12: Công tác lấp đất đầu cọc có kingpost | C12: Thời gian tiến hành lấp đầu cọc | D12: Bằng trực quan | E12: Tối thiểu 24 h sau khi kết thúc đổ bê tông | H12: TCVN 9395-2012
C13: Bơm hút dung dịch khoan trong hố cọc | D13: Bằng trực quan | E13: BPTC phê duyệt.
C14: Lấp base đến cao độ đỉnh casing | D14: Bằng trực quan | E14: BPTC phê duyệt.
C15: Tháo bàn dẫn hướng (đối với cọc có kingpost) và rút nhổ casing, đảm bảo casing được giữ thẳng đứng và đồng trục với cọc trong thời gian nhổ | D15: Máy toàn đạc | E15: Trong thời gian bêtông còn độ dẻo và chưa ninh kết
C16: Lấp đầu cọc đến cos mặt đất tự nhiên | D16: Bằng trực quan | E16: BPTC phê duyệt.
B18: Ghi chú: Chi tiết các chỉ tiêu xem tiêu chuẩn kỹ thuật quy định tại cột ghi chú
A19: GHI CHÚ CHUNG:
A32: CHỦ ĐẦU TƯ TRỢ LÝ XÂY NHÀ ĐƠN VỊ THI CÔNG

Sheet BM15
A2: CÔNG TY TNHH THƯƠNG MẠI VÀ DỊCH VỤ XÂY DỰNG NHÀ CỦA MÌNH AC | E2: CỘNG HÒA XÃ HỘI CHỦ NGHĨA VIỆT NAM
E3: Độc Lập - Tự Do - Hạnh Phúc
E4: Ngày…..tháng…..năm 202…..
A5: CHECKLIST KIỂM TRA | I5: Ấn để trở về sheet " Danh mục"
A6: Công trình: | C6: =+'DANH MỤC'!A2 -> Công trình:
C7: =+'DANH MỤC'!A3 -> Địa điểm:
C8: ="Công tác"&": "&'DANH MỤC'!B24 -> Công tác: Đào đất móng
A10: TT | B10: Công tác | C10: Công việc kiểm tra: | D10: Phương pháp kiểm tra | E10: Mức cho phép | F10: Đánh giá | H10: Ghi chú
F11: Đạt | G11: K.Đạt
A12: 1 | B12: Công tác phá đầu cọc | C12: Kiểm tra hiện trạng trước khi đào ( Cao độ, vị trí…) | D12: Máy toàn đạc | E12: Theo thực tế
C13: Kiểm tra quá trình đào theo BPTC ( hướng đào, vị trí, taluy, biện pháp an toàn lao động, bơm thoát nước…) | D13: Bằng mắt thường | E13: Theo biện pháp thi công đào đất được CĐT phê duyệt. | H13: TCVN 4447-2012
C14: Kiểm tra kích thước hố đào, vị trí. | D14: Đo bằng thước | E14: Theo biện pháp thi công đào đất được CĐT phê duyệt. | H14: TCVN 4447-2012
C15: Kiểm tra cao độ và công tác sửa chữa sau khi đào | D15: Máy toàn đạc | E15: Theo biện pháp thi công đào đất được CĐT phê duyệt. | H15: TCVN 4447-2012
C16: Cao độ sau khi đào | D16: Máy toàn đạc | E16: Theo biện pháp thi công đào đất được CĐT phê duyệt. | H16: TCVN 4447-2012
C17: Dọn vệ sinh bê tông đầu cọc | D17: Bằng mắt thường | E17: Bê tông đầu cọc sau khi phá phải chuyển ra ngoài công trường.
B18: Ghi chú: Chi tiết các chỉ tiêu xem tiêu chuẩn kỹ thuật quy định tại cột ghi chú
A19: GHI CHÚ CHUNG:
A32: CHỦ ĐẦU TƯ TRỢ LÝ XÂY NHÀ ĐƠN VỊ THI CÔNG

Sheet BM16
A2: CÔNG TY TNHH THƯƠNG MẠI VÀ DỊCH VỤ XÂY DỰNG NHÀ CỦA MÌNH AC | E2: CỘNG HÒA XÃ HỘI CHỦ NGHĨA VIỆT NAM
E3: Độc Lập - Tự Do - Hạnh Phúc
E4: Ngày…..tháng…..năm 202…..
A5: CHECKLIST KIỂM TRA | I5: Ấn để trở về sheet " Danh mục"
A6: Công trình: | C6: =+'DANH MỤC'!A2 -> Công trình:
C7: =+'DANH MỤC'!A3 -> Địa điểm:
C8: ="Công tác"&": "&'DANH MỤC'!B25 -> Công tác: Gia công lắp dựng cốt thép móng, cổ cột
A10: TT | B10: Công tác | C10: Công việc kiểm tra: | D10: Phương pháp kiểm tra | E10: Mức cho phép | F10: Đánh giá | H10: Ghi chú
F11: Đạt | G11: K.Đạt
A12: 1 | B12: Đế móng | C12: Tim, trục | D12: Thước dây | E12: Toàn bộ chiều dài ± 20mm
C13: Cọc neo vào đài móng (chiều dài thép neo, cao độ cọc ngàm vào đài móng) | D13: Đo bằng thước kẹp Bằng mắt thường | E13: Chiều dài thép neo 30d - 40d Chiều cao cọc ngàm vào đài móng 100mm
C14: Chủng loại, đường kính chiều dài, số lượng thép lớp trên, dưới | D14: Đo bằng thước kẹp Bằng mắt thường | H14: TCVN 4453-1995
C15: Chủng loại, đường kính chiều dài, số lượng thép dầm | D15: Đo bằng thước Bằng mắt thường | E15: ±10mm | H15: TCVN 4453-1995
C16: Chủng loại, đường kính, chiều dài, số lượng thép đai | D16: Đo bằng thước Bằng mắt thường | E16: Khoảng cách ± 10mm | H16: TCVN 4453-1995
C17: Chủng loại, đường kính, chiều dài, số lượng thép chống phình | D17: Đo bằng thước Bằng mắt thường | E17: Khoảng cách ± 10mm | H17: TCVN 4453-1995
C18: Vị trí, chiều dài các mối nối. | D18: Đo bằng thước Bằng mắt thường | H18: TCVN 4453-1995
C19: Chiều dày lớp BT bảo vệ | D19: Đo bằng thước Bằng mắt thường | H19: TCVN 4453-1995
B20: Cốt thép chờ cột | C20: Đường kính, số lượng, chiều dài, số lượng thép chủ | D20: Đo bằng thước kẹp Bằng mắt thường | H20: TCVN 4453-1995
C21: Đường kính, số lượng, chiều dài, số lượng thép đai | D21: Đo bằng thước Bằng mắt thường | E21: Khoảng cách ± 10mm | H21: TCVN 4453-1995
B22: Mạch ngừng | C22: Đục nhám,vệ sinh mạch ngừng | D22: Bằng mắt thường | E22: Theo biện pháp thi công được CĐT phê duyệt.
C23: Phun chất bảo vệ cốt thép chờ | D23: Bằng mắt thường | E23: Theo biện pháp thi công được CĐT phê duyệt.
B24: Ghi chú: Chi tiết các chỉ tiêu xem tiêu chuẩn kỹ thuật quy định tại cột ghi chú
A25: GHI CHÚ CHUNG:
A38: CHỦ ĐẦU TƯ TRỢ LÝ XÂY NHÀ ĐƠN VỊ THI CÔNG

Sheet BM17
A2: CÔNG TY TNHH THƯƠNG MẠI VÀ DỊCH VỤ XÂY DỰNG NHÀ CỦA MÌNH AC | E2: CỘNG HÒA XÃ HỘI CHỦ NGHĨA VIỆT NAM
E3: Độc Lập - Tự Do - Hạnh Phúc
E4: Ngày…..tháng…..năm 202…..
A5: CHECKLIST KIỂM TRA | I5: Ấn để trở về sheet " Danh mục"
A6: Công trình: | C6: =+'DANH MỤC'!A2 -> Công trình:
C7: =+'DANH MỤC'!A3 -> Địa điểm:
C8: ="Công tác"&": "&'DANH MỤC'!B26 -> Công tác: Gia công lắp dựng ván khuôn móng
A10: TT | B10: Công tác | C10: Công việc kiểm tra: | D10: Phương pháp kiểm tra | E10: Mức cho phép | F10: Đánh giá | H10: Ghi chú
F11: Đạt | G11: K.Đạt
A12: 1 | B12: Ván khuôn thành, mạch ngừng. | C12: Kiểm tra chất lượng ván khuôn trước khi gia công lắp đặt. | D12: Đo bằng thước Bằng mắt thường | E12: Theo chứng nhận chất lượng của nhà sản xuất. | H12: TCVN 4453-1995
C13: Hệ thống cây chống ván khuôn móng. | D13: Đo bằng thước Bằng mắt thường | E13: Sai số trên 1m ± 25mm Sai số trên toàn khẩu độ ± 75mm | H13: TCVN 4453-1995
C14: Vị trí ván khuôn | D14: Máy toàn đạc Đo bằng thước Bằng mắt thường | E14: Sai lệch vị trí ± 15mm | H14: TCVN 4453-1995
C15: Độ chắc chắn ổn định của ván khuôn. | D15: Bằng mắt thường, tay dung lắc các tấm ván khuôn. | E15: Theo biện pháp thi công được CĐT phê duyệt. | H15: TCVN 4453-1995
C16: Bề mặt ván khuôn ( Sạch, phẳng, không bám dính) | D16: Bằng mắt thường | E16: Mức độ gồ ghề giữa các tấm ván khuôn ± 3 mm. Bề mặt ván khuôn sạch, không dính tạp chất. | H16: TCVN 4453-1995
C17: Độ kín khít ván khuôn | D17: Đo bằng thước Bằng mắt thường | E17: Đảm bảo kín khít không mất nước xi măng ± 2 mm | H17: TCVN 4453-1995
C18: Độ thẳng đứng thành ván khuôn | D18: Kiểm tra bằng dọi Bằng mắt thường | H18: TCVN 4453-1995
C19: Vệ sinh ván khuôn | D19: Bằng mắt thường | E19: Không còn rác, bùn đất, mùn cưa, chất bẩn khác trên bề mặt ván khuôn. | H19: TCVN 4453-1995
C20: Lắp gioăng cản nước | D20: Bằng mắt thường | E20: Theo biện pháp thi công được CĐT phê duyệt.
B21: Ghi chú: Chi tiết các chỉ tiêu xem tiêu chuẩn kỹ thuật quy định tại cột ghi chú
A22: GHI CHÚ CHUNG:
A35: CHỦ ĐẦU TƯ TRỢ LÝ XÂY NHÀ ĐƠN VỊ THI CÔNG

Sheet BM18
A2: CÔNG TY TNHH THƯƠNG MẠI VÀ DỊCH VỤ XÂY DỰNG NHÀ CỦA MÌNH AC | E2: CỘNG HÒA XÃ HỘI CHỦ NGHĨA VIỆT NAM
E3: Độc Lập - Tự Do - Hạnh Phúc
E4: Ngày…..tháng…..năm 202…..
A5: CHECKLIST KIỂM TRA | I5: Ấn để trở về sheet " Danh mục"
A6: Công trình: | C6: =+'DANH MỤC'!A2 -> Công trình:
C7: =+'DANH MỤC'!A3 -> Địa điểm:
C8: ="Công tác"&": "&'DANH MỤC'!B27 -> Công tác: Đổ bê tông móng
A10: TT | B10: Công tác | C10: Công việc kiểm tra: | D10: Phương pháp kiểm tra | E10: Mức cho phép | F10: Đánh giá | H10: Ghi chú
F11: Đạt | G11: K.Đạt
A12: 1 | B12: Công tác đổ bê tông móng | C12: Công tác vệ sinh bề mặt bê tông lót, cốt thép, ván khuôn móng. | D12: Bằng mắt thường | E12: Theo biện pháp thi công được CĐT phê duyệt. | H12: TCVN 4453-1995
C13: Công tác chuẩn bị trước lúc đổ bê tông | D13: Bằng mắt thường | E13: Theo biện pháp thi công được CĐT phê duyệt và kế hoạch đổ bê tông. | H13: TCVN 4453-1995
C14: Kiểm tra độ sụt bê tông | D14: Đo bằng thước | E14: Theo mác BT thiết kế và BPTC đổ bê tông được phê duyệt. | H14: TCVN 4453-1995
C15: Lấy mẫu thí nghiệm bê tông | D15: Bằng mắt thường | E15: Lấy 03 mẫu BT hình lập phương kích thước 150x150x150 mm | H15: TCVN 3118:1993
C16: Tưới bám dính trước khi đổ bê tông. | D16: Bằng mắt thường | E16: Theo biện pháp thi công được CĐT phê duyệt. | H16: TCVN 4453-1995
C17: Quy trình đổ bê tông (Kỹ thuật đổ, đầm bê tông, mạch ngừng, cao độ…) | D17: Bằng mắt thường | E17: Theo biện pháp thi công được CĐT phê duyệt. | H17: TCVN 4453-1995
C18: Bảo dưỡng bê tông ban đầu và làm mặt | D18: Bằng mắt thường | E18: Theo biện pháp thi công được CĐT phê duyệt. | H18: TCVN 4453-1995
C19: Bảo dưỡng bê tông tiếp theo | D19: Bằng mắt thường | E19: Vùng A ( Từ Diễn Châu trở ra Bắc) + Hè 3 ngày đêm + Đông 4 ngày đêm Vùng B ( Phía đông trường sơn và từ Diễn Châu đến Thuận Hải). + Khô 4 ngày đêm + Mưa 2 ngày đêm Vùng C ( Tây Nguyên và Nam Bộ) + Khô 6 ngày đêm + Mưa 1 ngày đêm | H19: TCVN 4453-1995
C20: Bề mặt bê tông | D20: Bằng mắt thường | E20: Bề mặt nhẵn, đồng đều về màu sắc. Độ gồ ghề bề mặt đo bằng thước 2m không vượt quá 7mm. | H20: TCVN 4453-1995
B21: Ghi chú: Chi tiết các chỉ tiêu xem tiêu chuẩn kỹ thuật quy định tại cột ghi chú
A22: GHI CHÚ CHUNG:
A35: CHỦ ĐẦU TƯ TRỢ LÝ XÂY NHÀ ĐƠN VỊ THI CÔNG

Sheet BM19
A2: CÔNG TY TNHH THƯƠNG MẠI VÀ DỊCH VỤ XÂY DỰNG NHÀ CỦA MÌNH AC | E2: CỘNG HÒA XÃ HỘI CHỦ NGHĨA VIỆT NAM
E3: Độc Lập - Tự Do - Hạnh Phúc
E4: Ngày…..tháng…..năm 202…..
A5: CHECKLIST KIỂM TRA | I5: Ấn để trở về sheet " Danh mục"
A6: Công trình: | C6: =+'DANH MỤC'!A2 -> Công trình:
C7: =+'DANH MỤC'!A3 -> Địa điểm:
C8: ="Công tác"&": "&'DANH MỤC'!B28 -> Công tác: Lấp đất móng
A10: TT | B10: Công tác | C10: Công việc kiểm tra: | D10: Phương pháp kiểm tra | E10: Mức cho phép | F10: Đánh giá | H10: Ghi chú
F11: Đạt | G11: K.Đạt
A12: 1 | B12: Công tác lấp đất hố móng | C12: Biên bản nghiệm thu các cấu kiện, thiết bị che khuất. | D12: Bằng mắt thường | E12: Biên bản nghiệm thu công tác defect bề mặt bê tông móng. Biên bản nghiệm thu các thiết bị điện nước che khuất. | H12: NĐ46/2015NĐ-CP: Về quản lý chất lượng và bảo trì công trình xây dựng.
C13: Công tác chuẩn bị trước lúc lấp hố móng | D13: Bằng mắt thường | E13: BPTC lấp đất móng được CĐT phê duyệt. Máy móc thi công lấp đất móng được kiểm tra đảm bảo an toàn. | H13: TCVN 4447-2012
C14: Kiểm tra chất lượng đất lấp hố móng. | D14: Bằng mắt thường | E14: Theo biện pháp thi công lấp đất được CĐT phê duyệt.
C15: Vệ sinh mặt bằng hố móng | D15: Bằng mắt thường | E15: Hố móng được vệ sinh sạch trạc vữa, đất bùn, không đọng nước.
C16: Kiểm tra quá trình thi công lấp đất | D16: Bằng mắt thường Máy toàn đạc | E16: Theo BPTC lấp đất được CĐT phê duyệt. Lấp và đầm đất theo lớp 0,3m. | H16: TCVN 4447-2012
C17: Kiểm tra quá trình đầm chặt đất | D17: Kết quả thí nghiệm độ chặt K | E17: Theo biện pháp thi công lấp đất được CĐT phê duyệt. + Đối với đất dính:10% của độ ẩm là tốt nhất. + Đối với đất không dính: 20% của độ ẩm là tốt nhất. | H17: TCVN 8730-2012
C18: Kiểm tra bề mặt nền sau khi lấp | D18: Bằng mắt thường Máy toàn đạc | E18: Bề mặt nền phẳng đúng cao độ thiết kế quy định
B19: Ghi chú: Chi tiết các chỉ tiêu xem tiêu chuẩn kỹ thuật quy định tại cột ghi chú
A20: GHI CHÚ CHUNG:
A33: CHỦ ĐẦU TƯ TRỢ LÝ XÂY NHÀ ĐƠN VỊ THI CÔNG

Sheet BM20
A2: CÔNG TY TNHH THƯƠNG MẠI VÀ DỊCH VỤ XÂY DỰNG NHÀ CỦA MÌNH AC | E2: CỘNG HÒA XÃ HỘI CHỦ NGHĨA VIỆT NAM
E3: Độc Lập - Tự Do - Hạnh Phúc
E4: Ngày…..tháng…..năm 202…..
A5: CHECKLIST KIỂM TRA | I5: Ấn để trở về sheet " Danh mục"
A6: Công trình: | C6: =+'DANH MỤC'!A2 -> Công trình:
C7: =+'DANH MỤC'!A3 -> Địa điểm:
C8: ="Công tác"&": "&'DANH MỤC'!B30 -> Công tác: Gia công lắp dựng cốt thép cột, vách
A10: TT | B10: Công tác | C10: Công việc kiểm tra: | D10: Phương pháp kiểm tra | E10: Mức cho phép | F10: Đánh giá | H10: Ghi chú
F11: Đạt | G11: K.Đạt
A12: 1 | B12: Công tác lắp dựng cốt thép cột vách | C12: Đục nhám bê tông chân cột, vách | D12: Bằng mắt thường | E12: Bề mặt bê tông sạch tạp chất, có độ nhám bề mặt để tăng liên kết bê tông cột vách.
C13: Vệ sinh cốt thép chờ cột vách. | D13: Bằng mắt thường | E13: Thép chờ cột vách phải được vệ sinh sạch sẽ tạp chất.
C14: Chủng loại, đường kính, chiều dài thép chủ cột, vách. | D14: Đo bằng thước Bằng mắt thường | H14: TCVN 4453-1995
C15: Chủng loại, đường kính, chiều dài thép đai cột, vách. | D15: Đo bằng thước Bằng mắt thường | E15: Khoảng cách ± 10mm | H15: TCVN 4453-1995
C16: Vị trí, chiều dài mối nối | D16: Bằng mắt thường Đo bằng thước | E16: Theo thiết kế Chiều dài nối 40d Thép vằn nối ≤50% diện tích mặt cắt ngang cốt thép. Thép trơn nối ≤25% diện tích mặt cắt ngang cốt thép. | H16: TCVN 4453-1995
C17: Vị trí các thanh thép | D17: Đo bằng thước | H17: TCVN 4453-1995
C18: Chiều dày lớp bê tông bảo vệ | D18: Đo bằng thước | H18: TCVN 4453-1995
C19: Vệ sinh sau khi lắp đặt | D19: Bằng mắt thường | E19: Thép cột vách được vệ sinh sạch tạp chất
B20: Ghi chú: Chi tiết các chỉ tiêu xem tiêu chuẩn kỹ thuật quy định tại cột ghi chú
A21: GHI CHÚ CHUNG:
A34: CHỦ ĐẦU TƯ TRỢ LÝ XÂY NHÀ ĐƠN VỊ THI CÔNG

Sheet BM21
A2: CÔNG TY TNHH THƯƠNG MẠI VÀ DỊCH VỤ XÂY DỰNG NHÀ CỦA MÌNH AC | E2: CỘNG HÒA XÃ HỘI CHỦ NGHĨA VIỆT NAM
E3: Độc Lập - Tự Do - Hạnh Phúc
E4: Ngày…..tháng…..năm 202…..
A5: CHECKLIST KIỂM TRA | I5: Ấn để trở về sheet " Danh mục"
A6: Công trình: | C6: =+'DANH MỤC'!A2 -> Công trình:
C7: =+'DANH MỤC'!A3 -> Địa điểm:
C8: ="Công tác"&": "&'DANH MỤC'!B31 -> Công tác: Gia công lắp dựng ván khuôn cột, vách
A10: TT | B10: Công tác | C10: Công việc kiểm tra: | D10: Phương pháp kiểm tra | E10: Mức cho phép | F10: Đánh giá | H10: Ghi chú
F11: Đạt | G11: K.Đạt
A12: 1 | B12: Công tác GCLD ván khuôn cột vách | C12: Kiểm tra chất lượng ván khuôn trước khi gia công lắp đặt. | D12: Đo bằng thước Bằng mắt thường | E12: Theo chứng nhận chất lượng của nhà sản xuất.
C13: Vị trí, kích thước hình học ván khuôn cột vách. | D13: Máy toàn đạc Đo bằng thước Bằng mắt thường | E13: Sai lệch vị trí ± 8mm | H13: TCVN 4453-1995
C14: Bề mặt ván khuôn ( Sạch, phẳng, không bám dính) | D14: Bằng mắt thường | E14: Mức độ gồ ghề giữa các tấm ván khuôn ± 3 mm. Bề mặt ván khuôn sạch, không dính tạp chất. | H14: TCVN 4453-1995
C15: Độ kín khít của ván khuôn | D15: Bằng mắt thường | E15: Ván khuôn được ghép kín khít đảm bảo không mất nước xi măng khi đổ và đầm bê tông. | H15: TCVN 4453-1995
C16: Độ thẳng đứng của ván khuôn | D16: Bằng mắt thường Máy laser | E16: Sai lệch vị trí ± 8mm | H16: TCVN 4453-1995
C17: Độ chắc chắn của ván khuôn | D17: Bằng mắt thường, tay dung lắc các tấm ván khuôn. | E17: Theo biện pháp thi công được CĐT phê duyệt. | H17: TCVN 4453-1995
C18: Độ ổn định chắc chắn của cây chống cột, vách. | D18: Bằng mắt thường, tay dung lắc các cây chống. | E18: Theo biện pháp thi công được CĐT phê duyệt. | H18: TCVN 4453-1995
C19: Công tác vệ sinh sau khi lắp đặt | D19: Bằng mắt thường | E19: Không còn rác, bùn đất, mùn cưa, chất bẩn khác trên bề mặt ván khuôn.
B20: Ghi chú: Chi tiết các chỉ tiêu xem tiêu chuẩn kỹ thuật quy định tại cột ghi chú
A21: GHI CHÚ CHUNG:
A34: CHỦ ĐẦU TƯ TRỢ LÝ XÂY NHÀ ĐƠN VỊ THI CÔNG

Sheet BM22
A2: CÔNG TY TNHH THƯƠNG MẠI VÀ DỊCH VỤ XÂY DỰNG NHÀ CỦA MÌNH AC | E2: CỘNG HÒA XÃ HỘI CHỦ NGHĨA VIỆT NAM
E3: Độc Lập - Tự Do - Hạnh Phúc
E4: Ngày…..tháng…..năm 202…..
A5: CHECKLIST KIỂM TRA | I5: Ấn để trở về sheet " Danh mục"
A6: Công trình: | C6: =+'DANH MỤC'!A2 -> Công trình:
C7: =+'DANH MỤC'!A3 -> Địa điểm:
C8: ="Công tác"&": "&'DANH MỤC'!B32 -> Công tác: Công tác đổ bê tông cột, vách
A10: TT | B10: Công tác | C10: Công việc kiểm tra: | D10: Phương pháp kiểm tra | E10: Mức cho phép | F10: Đánh giá | H10: Ghi chú
F11: Đạt | G11: K.Đạt
A12: 1 | B12: Công tác đổ bê tông cột vách | C12: Vệ sinh, tưới bám dính trước khi đổ bê tông. | D12: Bằng mắt thường | E12: Theo BPTC đổ bê tông cột, vách được CĐT phê duyệt.
C13: Quá trình đổ bê tông. ( Kỹ thuật đổ, đầm bê tông) | D13: Bằng mắt thường | E13: - Cột có chiều cao nhỏ hơn 5m đổ bê tông liên tục. - Cột vách cao hơn 5 m chia thành nhiều đợt đổ bê tông, vị trí mạch ngừng phải theo BPTC được duyệt. | H13: TCVN 4453-1995
C14: Cao độ dừng đổ bê tông cột vách. | D14: Đo bằng thước | E14: - Ở mặt trên của móng. - Ở mặt dưới của xà, dầm ( thường cách đáy dầm 2 cm) | H14: TCVN 4453-1995
C15: Bề mặt bê tông sau khi tháo ván khuôn | D15: Bằng mắt thường | E15: Bề mặt bê tông phải phẳng nhẵn, góc cạnh, đồng đều về màu sắc. | H15: TCVN 4453-1995
C16: Bảo dưỡng bê tông | D16: Bằng mắt thường | E16: Vùng A ( Từ Diễn Châu trở ra Bắc) + Hè 3 ngày đêm + Đông 4 ngày đêm Vùng B ( Phía đông trường sơn và từ Diễn Châu đến Thuận Hải). + Khô 4 ngày đêm + Mưa 2 ngày đêm Vùng C ( Tây Nguyên và Nam Bộ) + Khô 6 ngày đêm + Mưa 1 ngày đêm | H16: TCVN 4453-1995
B17: Ghi chú: Chi tiết các chỉ tiêu xem tiêu chuẩn kỹ thuật quy định tại cột ghi chú
A18: GHI CHÚ CHUNG:
A31: CHỦ ĐẦU TƯ TRỢ LÝ XÂY NHÀ ĐƠN VỊ THI CÔNG

Sheet BM23
A2: CÔNG TY TNHH THƯƠNG MẠI VÀ DỊCH VỤ XÂY DỰNG NHÀ CỦA MÌNH AC | E2: CỘNG HÒA XÃ HỘI CHỦ NGHĨA VIỆT NAM
E3: Độc Lập - Tự Do - Hạnh Phúc
E4: Ngày…..tháng…..năm 202…..
A5: CHECKLIST KIỂM TRA | I5: Ấn để trở về sheet " Danh mục"
A6: Công trình: | C6: =+'DANH MỤC'!A2 -> Công trình:
C7: =+'DANH MỤC'!A3 -> Địa điểm:
C8: ="Công tác"&": "&'DANH MỤC'!B33 -> Công tác: Gia công lắp dựng ván khuôn dầm sàn
A10: TT | B10: Công tác | C10: Công việc kiểm tra: | D10: Phương pháp kiểm tra | E10: Mức cho phép | F10: Đánh giá | H10: Ghi chú
F11: Đạt | G11: K.Đạt
A12: 1 | B12: Công tác GCLD ván khuôn dầm sàn | C12: Kiểm tra chất lượng ván khuôn trước khi gia công lắp đặt. | D12: Đo bằng thước Bằng mắt thường | E12: Theo chứng nhận chất lượng của nhà sản xuất.
C13: Vị trí, cao độ ván khuôn | D13: Máy toàn đạc Đo bằng thước | E13: Sai lệch vị trí ± 10mm | H13: TCVN 4453-1995
C14: Độ chắc chắn ổn định của ván khuôn. | D14: Bằng mắt thường, tay dung lắc các tấm ván khuôn. | E14: Theo biện pháp thi công được CĐT phê duyệt. | H14: TCVN 4453-1995
C15: Bề mặt ván khuôn ( Sạch, phẳng, không bám dính) | D15: Bằng mắt thường | E15: Mức độ gồ ghề giữa các tấm ván khuôn ± 3 mm. Bề mặt ván khuôn sạch, không dính tạp chất. | H15: TCVN 4453-1995
C16: Độ kín khít ván khuôn | D16: Đo bằng thước Bằng mắt thường | E16: Đảm bảo kín khít không mất nước xi măng ± 2 mm | H16: TCVN 4453-1995
C17: Độ thẳng đứng thành ván khuôn | D17: Kiểm tra bằng dọi Bằng mắt thường | H17: TCVN 4453-1995
C18: Hệ thống cây chống dầm sàn. | D18: Đo bằng thước Bằng mắt thường | E18: Sai số trên 1m ± 25mm Sai số trên toàn khẩu độ ± 75mm | H18: TCVN 4453-1995
C19: Vệ sinh ván khuôn | D19: Bằng mắt thường | E19: Không còn rác, bùn đất, mùn cưa, chất bẩn khác trên bề mặt ván khuôn. | H19: TCVN 4453-1995
B20: Ghi chú: Chi tiết các chỉ tiêu xem tiêu chuẩn kỹ thuật quy định tại cột ghi chú
A21: GHI CHÚ CHUNG:
A34: CHỦ ĐẦU TƯ TRỢ LÝ XÂY NHÀ ĐƠN VỊ THI CÔNG

Sheet BM24
A2: CÔNG TY TNHH THƯƠNG MẠI VÀ DỊCH VỤ XÂY DỰNG NHÀ CỦA MÌNH AC | E2: CỘNG HÒA XÃ HỘI CHỦ NGHĨA VIỆT NAM
E3: Độc Lập - Tự Do - Hạnh Phúc
E4: Ngày…..tháng…..năm 202…..
A5: CHECKLIST KIỂM TRA | I5: Ấn để trở về sheet " Danh mục"
A6: Công trình: | C6: =+'DANH MỤC'!A2 -> Công trình:
C7: =+'DANH MỤC'!A3 -> Địa điểm:
C8: ="Công tác"&": "&'DANH MỤC'!B34 -> Công tác: Gia công lắp dựng cốt thép dầm sàn
A10: TT | B10: Công tác | C10: Công việc kiểm tra: | D10: Phương pháp kiểm tra | E10: Mức cho phép | F10: Đánh giá | H10: Ghi chú
F11: Đạt | G11: K.Đạt
A12: 1 | B12: Dầm | C12: Chủng loại , đường kính, chiều dài thép chủ. | D12: Đo bằng thước kẹp Bằng mắt thường | H12: TCVN 4453-1995
C13: Chủng loại , đường kính, chiều dài thép chờ. | D13: Đo bằng thước Bằng mắt thường | H13: TCVN 4453-1995
C14: Chủng loại, đường kính, chiều dài thép đai | D14: Đo bằng thước Bằng mắt thường | E14: Khoảng cách ± 10mm | H14: TCVN 4453-1995
C15: Uốn nắn vệ sinh cốt thép chờ dầm, thép gia cường. | D15: Đo bằng thước Bằng mắt thường | E15: Khoảng cách ± 10mm | H15: TCVN 4453-1995
B16: Sàn | C16: Chủng loại , đường kính, chiều dài thép lớp dưới. | D16: Đo bằng thước Bằng mắt thường | E16: Khoảng cách ±10mm | H16: TCVN 4453-1995
C17: Chủng loại , đường kính, chiều dài thép lớp trên. | D17: Đo bằng thước Bằng mắt thường | E17: Khoảng cách ±10mm | H17: TCVN 4453-1995
C18: Chủng loại , đường kính, chiều dài thép gia cường lỗ mở | D18: Đo bằng thước Bằng mắt thường | E18: Một mét dài ± 5mm | H18: TCVN 4453-1995
C19: Lắp đặt gioăng mạch ngừng sàn | D19: Bằng mắt thường | E19: Biện pháp TC được CĐT phê duyệt
B20: Xử lý mạch ngừng dầm sàn | C20: Đục tẩy bê tông mạch ngừng làm sạch, tạo nhám. | D20: Bằng mắt thường | E20: Biện pháp TC được CĐT phê duyệt
C21: Uốn nắn vệ sinh cốt thép chờ dầm, sàn | D21: Bằng mắt thường | H21: TCVN 4453-1995
C22: Chủng loại, đường kính, chiều dài thép chờ. | D22: Đo bằng thước Bằng mắt thường | H22: TCVN 4453-1995
C23: Vị trí các thanh thép | D23: Đo bằng thước Bằng mắt thường | E23: Khoảng cách ±10mm | H23: TCVN 4453-1995
C24: Vị trí, chiều dài các mối nối. | D24: Đo bằng thước Bằng mắt thường | E24: Theo thiết kế Vùng chịu kéo 40d Vùng chịu nén 30d Thép vằn nối ≤50% diện tích mặt cắt ngang cốt thép. Thép trơn nối ≤25% diện tích mặt cắt ngang cốt thép. | H24: TCVN 4453-1995
C25: Chiều dày lớp BT bảo vệ | D25: Đo bằng thước Bằng mắt thường | E25: ± 3 mm ( a≤15mm) ± 5 mm ( a≥15mm) | H25: TCVN 4453-1995
C26: Công tác vệ sinh cốt thép | D26: Bằng mắt thường | E26: Theo biện pháp thi công được CĐT phê duyệt.
C27: Lắp đặt lưới mạch ngừng | D27: Bằng mắt thường | E27: Theo biện pháp thi công được CĐT phê duyệt.
B28: Ghi chú: Chi tiết các chỉ tiêu xem tiêu chuẩn kỹ thuật quy định tại cột ghi chú
A29: GHI CHÚ CHUNG:
A42: CHỦ ĐẦU TƯ TRỢ LÝ XÂY NHÀ ĐƠN VỊ THI CÔNG

Sheet BM25
A2: CÔNG TY TNHH THƯƠNG MẠI VÀ DỊCH VỤ XÂY DỰNG NHÀ CỦA MÌNH AC | E2: CỘNG HÒA XÃ HỘI CHỦ NGHĨA VIỆT NAM
E3: Độc Lập - Tự Do - Hạnh Phúc
E4: Ngày…..tháng…..năm 202…..
A5: CHECKLIST KIỂM TRA | I5: Ấn để trở về sheet " Danh mục"
A6: Công trình: | C6: =+'DANH MỤC'!A2 -> Công trình:
C7: =+'DANH MỤC'!A3 -> Địa điểm:
C8: ="Công tác"&": "&'DANH MỤC'!B35 -> Công tác: Bê tông dầm sàn
A10: TT | B10: Công tác | C10: Công việc kiểm tra: | D10: Phương pháp kiểm tra | E10: Mức cho phép | F10: Đánh giá | H10: Ghi chú
F11: Đạt | G11: K.Đạt
A12: 1 | B12: Công tác đổ bê tông dầm sàn | C12: Vệ sinh tổng thể (đầu cột, vách, cốt thép, ván khuôn dầm sàn) | D12: Bằng mắt thường | E12: Theo BPTC đổ bê tông cột, vách được CĐT phê duyệt.
C13: Vệ sinh, tưới bám dính đầu cột, vách trước khi đổ bê tông. | D13: Bằng mắt thường | E13: Theo BPTC đổ bê tông cột, vách được CĐT phê duyệt.
C14: Quá trình đổ bê tông. (Kỹ thuật đổ, đầm bê tông) | D14: Bằng mắt thường | E14: - Hướng đổ song song với dầm phụ thì mạch ngừng thi công bố trí trong khoảng 1/3 đoạn giữa của nhịp dầm. - Hướng đổ song song với dầm chính thì mạch ngừng thi công bố trí ở trong hai khoảng giữa của nhịp dầm và sàn ( mỗi khoảng dài 1/4 nhịp) - Bước di chuyển của đầm dùi không vượt quá 1,5 bán kính tác dụng của đầm và cắm sâu vào lớp bê tông đã đổ trước 10cm. - Dấu hiệu nhận biết bê tông đã được đầm kỹ là vữa xi măng nổi lên bề mặt và bọt khí không còn nữa. | H14: TCVN 4453-1995
C15: Làm mặt, cao độ mặt bê tông. | D15: Bằng mắt thường Máy Thủy Bình | H15: TCVN 4453-1995
C16: Bảo dưỡng bê tông tiếp theo | D16: Bằng mắt thường | E16: Vùng A ( Từ Diễn Châu trở ra Bắc) + Hè 3 ngày đêm + Đông 4 ngày đêm Vùng B ( Phía đông trường sơn và từ Diễn Châu đến Thuận Hải). + Khô 4 ngày đêm + Mưa 2 ngày đêm Vùng C ( Tây Nguyên và Nam Bộ) + Khô 6 ngày đêm + Mưa 1 ngày đêm | H16: TCVN 4453-1995
C17: Bề mặt bê tông hoàn thiện | D17: Bằng mắt thường | E17: Mức độ gồ ghề của bề mặt bê tông khi ốp thước 2m không vượt quá 7mm. | H17: TCVN 4453-1995
B18: Ghi chú: Chi tiết các chỉ tiêu xem tiêu chuẩn kỹ thuật quy định tại cột ghi chú
A19: GHI CHÚ CHUNG:
A32: CHỦ ĐẦU TƯ TRỢ LÝ XÂY NHÀ ĐƠN VỊ THI CÔNG

Sheet BM26
A2: CÔNG TY TNHH THƯƠNG MẠI VÀ DỊCH VỤ XÂY DỰNG NHÀ CỦA MÌNH AC | E2: CỘNG HÒA XÃ HỘI CHỦ NGHĨA VIỆT NAM
E3: Độc Lập - Tự Do - Hạnh Phúc
E4: Ngày…..tháng…..năm 202…..
A5: CHECKLIST KIỂM TRA | I5: Ấn để trở về sheet " Danh mục"
A6: Công trình: | C6: =+'DANH MỤC'!A2 -> Công trình:
C7: =+'DANH MỤC'!A3 -> Địa điểm:
C8: ="Công tác"&": "&'DANH MỤC'!B37 -> Công tác: Xây tường
A10: TT | B10: Công tác | C10: Công việc kiểm tra: | D10: Phương pháp kiểm tra | E10: Mức cho phép | F10: Đánh giá | H10: Ghi chú
F11: Đạt | G11: K.Đạt
C12: Cấp phối vữa xi măng | D12: Bằng mắt thường Lấy mẫu thí nghiệm | E12: Kết quả mẫu thí nghiệm
C13: Loại gạch được sử dụng cho từng khu vực, vị trí. | D13: Bằng mắt thường. Đo bằng thước. | E13: Bản vẽ Shopdrawing Giấy chứng nhận về quy cách và chất lượng gạch do nhà sản xuất cấp.
C14: Vị trí tường xây | D14: Đo bằng thước | E14: ± 10mm | H14: TCVN 4085-2011
C15: Nghiệm thu chân cơ căng dây, thả lèo | D15: Bằng mắt thường. Đo bằng thước. | E15: ± 10mm | H15: TCVN 4085-2011
C16: - Khoan cắm thép liên kết tường xây. - Lớp hồ dầu tiếp giáp giữa tường và BTCT | D16: Bằng mắt thường. Đo bằng thước. | E16: Tường 110: Khoan cấy 01 râu thép phi 8, neo vào BT 10d, nhô ra ngoài tường 30cm. Khoảng cách râu a =500mm. Tường 220: Khoan cấy 02 râu thép phi 8, neo vào BT 10d, nhô ra ngoài tường 30cm. Khoảng cách râu a = 500mm. | H16: TCVN 4085-2011
C17: Quy cách xây ( quy định về gạch quay ngang, gạch chèn đỉnh tường, kích thước khối xây…) | D17: Bằng mắt thường. Đo bằng thước. | E17: - Hàng gạch chân cơ xây gạch đặc. - Hàng gạch đỉnh tường xây gạch đặc vỉa nghiêng 45-60 độ. - Tường biên xây gạch đặc, tường vệ sinh xây gạch đặc 30 cm. - Xây tường 220 ba dọc một ngang hoặc 05 dọc 01 ngang. - Chiều cao mỗi đợt xây không vượt quá 1,5m. | H17: TCVN 4085-2011
C18: Công tác thi công trụ tường, giằng tường, lanh tô. | D18: Bằng mắt thường. Đo bằng thước. | E18: - Lanh tô gác vào đầu tường 250mm | H18: TCVN 4085-2011
C19: Chiều dày độ đặc chắc, vệ sinh mạch vữa. | D19: Bằng mắt thường. Đo bằng thước. | E19: - Mạch vữa đứng trung bình 10mm, mạch vữa ngang 8-15mm, các mạch đứng so le nhau ít nhất là 50mm. | H19: TCVN 4085-2011
C20: Độ ngang bằng, thẳng đứng, mặt phẳng, vuông góc, mạch vữa đặc chắc, thông thủy. | D20: Máy laser Bằng mắt thường. Đo bằng thước. | E20: + Độ ngang bằng ± 10mm + Mặt phẳng ốp thước 2m không quá 10mm. | H20: TCVN 4085-2011
C21: Vị trí, kích thước cửa, kích thước lỗ mở. | D21: Bằng mắt thường. Đo bằng thước. | E21: ± 10mm | H21: TCVN 4085-2011
C22: Vệ sinh bảo dưỡng, xử lý khuyết tật và các công việc khác. | D22: Bằng mắt thường. | E22: Biện pháp TC xây trát được CĐT phê duyệt.
B23: Ghi chú: Chi tiết các chỉ tiêu xem tiêu chuẩn kỹ thuật quy định tại cột ghi chú
A24: GHI CHÚ CHUNG:
A37: CHỦ ĐẦU TƯ TRỢ LÝ XÂY NHÀ ĐƠN VỊ THI CÔNG

Sheet BM27
A2: CÔNG TY TNHH THƯƠNG MẠI VÀ DỊCH VỤ XÂY DỰNG NHÀ CỦA MÌNH AC | E2: CỘNG HÒA XÃ HỘI CHỦ NGHĨA VIỆT NAM
E3: Độc Lập - Tự Do - Hạnh Phúc
E4: Ngày…..tháng…..năm 202…..
A5: CHECKLIST KIỂM TRA | I5: Ấn để trở về sheet " Danh mục"
A6: Công trình: | C6: =+'DANH MỤC'!A2 -> Công trình:
C7: =+'DANH MỤC'!A3 -> Địa điểm:
C8: ="Công tác"&": "&'DANH MỤC'!B38 -> Công tác: Lanh tô, trụ tường
A10: TT | B10: Công tác | C10: Công việc kiểm tra: | D10: Phương pháp kiểm tra | E10: Mức cho phép | F10: Đánh giá | H10: Ghi chú
F11: Đạt | G11: K.Đạt
C12: Vị trí thi công lanh tô, trụ tường | D12: Bằng mắt thường Đo bằng thước | E12: Bản vẽ Shopdrawing phê duyệt
C13: Khoan cấy Ramset thép chờ lanh tô, trụ tường ( nếu có | D13: Đo bằng thước Thí nghiệm kiểm tra chống nhổ. | H13: TCVN 8163-2009
C14: Vị trí, chủng loại đường kính cốt thép lanh tô, trụ tường. | D14: Bằng mắt thường Lấy mẫu thí nghiệm | E14: Sai số chiều dài thép chủ trên 1m dài: ± 5mm Sai số khoảng cách thép chủ, thép đai: ± 10mm | H14: TCVN 4453-1995
C15: Vị trí, kích thước hình học ván khuôn lanh tô, trụ tường. | D15: Bằng mắt thường. Đo bằng thước. | E15: - Bề mặt ván khuôn phẳng nhẵn, độ gồ ghề không quá 3mm. - Sai số khoảng cách cây chống: 25mm/ 1md; trên toàn khẩu độ 75mm. - Ván khuôn kín khít không mất nước xi măng | H15: TCVN 4453-1995
C16: Vệ sinh cốt thép lanh tô, bổ trụ | D16: Bằng mắt thường. Đo bằng thước. | E16: BPTC lanh tô, bổ trụ phê duyệt.
C17: Kiểm tra quá trình đổ bê tông lanh tô bổ trụ. | D17: Bằng mắt thường. Đo bằng thước. | E17: + Đầm bê tông: nước xi măng nổi lên bề mặt và bọt khí không còn nữa. + Làm mặt bê tông phẳng nhẵn. | H17: TCVN 3118-1993 TCVN 3106-1993
C18: Nghiệm thu công tác đổ bê tông lanh tô. | D18: Bằng mắt thường. Đo bằng thước. | H18: TCVN 4453-1995
C19: Công tác bảo dưỡng bê tông lanh tô | D19: Kiểm tra quá trình bảo dưỡng BT. | E19: Vùng A ( Từ Diễn Châu trở ra Bắc) + Hè 3 ngày đêm + Đông 4 ngày đêm Vùng B ( Phía đông trường sơn và từ Diễn Châu đến Thuận Hải). + Khô 4 ngày đêm + Mưa 2 ngày đêm Vùng C ( Tây Nguyên và Nam Bộ) + Khô 6 ngày đêm + Mưa 1 ngày đêm | H19: TCVN 4453-1995
B20: Ghi chú: Chi tiết các chỉ tiêu xem tiêu chuẩn kỹ thuật quy định tại cột ghi chú
A21: GHI CHÚ CHUNG:
A34: CHỦ ĐẦU TƯ TRỢ LÝ XÂY NHÀ ĐƠN VỊ THI CÔNG

Sheet BM28
A2: CÔNG TY TNHH THƯƠNG MẠI VÀ DỊCH VỤ XÂY DỰNG NHÀ CỦA MÌNH AC | E2: CỘNG HÒA XÃ HỘI CHỦ NGHĨA VIỆT NAM
E3: Độc Lập - Tự Do - Hạnh Phúc
E4: Ngày…..tháng…..năm 202…..
A5: CHECKLIST KIỂM TRA | I5: Ấn để trở về sheet " Danh mục"
A6: Công trình: | C6: =+'DANH MỤC'!A2 -> Công trình:
C7: =+'DANH MỤC'!A3 -> Địa điểm:
C8: ="Công tác"&": "&'DANH MỤC'!B39 -> Công tác: Tô/Trát
A10: TT | B10: Công tác | C10: Công việc kiểm tra: | D10: Phương pháp kiểm tra | E10: Mức cho phép | F10: Đánh giá | H10: Ghi chú
F11: Đạt | G11: K.Đạt
B12: Công tác trát tường | C12: Cấp phối vữa trát tường trong | D12: Lấy mẫu thí nghiệm | E12: Kết quả mẫu thí nghiệm
C13: Cấp phối vữa trát tường ngoài, trần, cầu thang, má cửa… | D13: Lấy mẫu thí nghiệm | E13: Kết quả mẫu thí nghiệm
C14: Tạo nhám đối với trần, cột, vách bê tông. | D14: Bằng mắt thường. | E14: Vữa Xi măng cát tỷ lệ 1:1 để khô sau 12h( nhưng không quá 36h)
C15: Vệ sinh tạo ẩm bề mặt tường, trần ( trước khi trát) | D15: Bằng mắt thường. | E15: BPTC trát tường dầm trần được phê duyệt
C16: Đóng lưới liên kết tại các vị trí tiếp giáp giữa bê tông và tường. | D16: Đo bằng thước. | E16: BPTC đóng lưới được phê duyệt (Tại vị trí tiếp giáp chờm về mỗi phía tối thiểu là 5 cm) | H16: TCVN 4085-2011
C17: Kiểm tra công tác đắp mốc | D17: Bằng mắt thường. Đo bằng thước. | H17: TCVN 4085-2011
C18: Trát 02 lớp đối với cấu kiện tường cột, dầm ( các vị trí trát dày quá quy định tuân theo BPTC được phê duyệt) | D18: Bằng mắt thường. Đo bằng thước. | E18: Chiều dày lớp trát từ 8- 20mm. Trát dày lớn hơn 20mm phải đóng lưới. Chiều dày mỗi lần trát mỏng nhất 5mm lớn nhất 8mm. | H18: TCVN 4085-2011
C19: Công tác đắp gờ, phào, chỉ | D19: Bằng mắt thường. | E19: Bản vẽ Shopdrawing phê duyệt | H19: TCVN 4085-2011
C20: Kiểm tra chất lượng trát: Gõ bộp, độ phẳng, thẳng, vết nứt, tạp chất, góc cạnh sắc nét, thẩm mỹ… của bề mặt trát. | D20: Bằng mắt thường Thước tầm Máy laser | E20: Bề mặt phẳng nhẵn, không nứt nẻ chân chim, không bị bộp. - Ốp thước 2m trát trong khe hở không quá 2mm( cả bức tường không quá 10mm). - Ốp thước 2m trát ngoài khe hở không quá 3mm( cả bức tường không quá 10mm). | H20: TCVN 4085-2011
C21: Kích thước cửa, lỗ mở | D21: Máy laser Đo bằng thước. | E21: Sai số cho phép +5mm
C22: Công tác sửa chữa khuyết tật (nếu có), vệ sinh và bảo dưỡng | D22: Bằng mắt thường. | E22: Sau khi trát xong 6h bảo dưỡng 03 ngày. | H22: TCVN 4085-2011
B23: Ghi chú: Chi tiết các chỉ tiêu xem tiêu chuẩn kỹ thuật quy định tại cột ghi chú
A24: GHI CHÚ CHUNG:
A37: CHỦ ĐẦU TƯ TRỢ LÝ XÂY NHÀ ĐƠN VỊ THI CÔNG

Sheet BM29
A2: CÔNG TY TNHH THƯƠNG MẠI VÀ DỊCH VỤ XÂY DỰNG NHÀ CỦA MÌNH AC | E2: CỘNG HÒA XÃ HỘI CHỦ NGHĨA VIỆT NAM
E3: Độc Lập - Tự Do - Hạnh Phúc
E4: Ngày…..tháng…..năm 202…..
A5: CHECKLIST KIỂM TRA | I5: Ấn để trở về sheet " Danh mục"
A6: Công trình: | C6: =+'DANH MỤC'!A2 -> Công trình:
C7: =+'DANH MỤC'!A3 -> Địa điểm:
C8: ="Công tác"&": "&'DANH MỤC'!B40 -> Công tác: Chống thấm nền vệ sinh
A10: TT | B10: Công tác | C10: Công việc kiểm tra: | D10: Phương pháp kiểm tra | E10: Mức cho phép | F10: Đánh giá | H10: Ghi chú
F11: Đạt | G11: K.Đạt
B12: Công tác chống thấm nền vệ sinh | C12: Kiểm tra chất lượng các loại vật liệu chống thấm. | D12: Bằng mắt thường Lấy mẫu thí nghiệm | E12: Chủng loại theo HĐ (VL đã được nghiệm thu đầu vào) | H12: TCVN 367-2006
C13: Kiểm tra bề mặt vệ sinh nền: Đục tẩy tạp chất, trám trít vị trí khuyết tật. | D13: Bằng mắt thường Lấy mẫu thí nghiệm | E13: - Đục sạch tạp chất trên bề mặt nền. - Các ty thép dùng đục, máy cắt, gió đá cắt sâu so với bề mặt bê tông 2 cm. - Các vị trí vết nứt rạn bê tông cắt rộng 1-2 cm, sâu 2 cm. | H13: TCVN 367-2006
C14: Cố định vị trí ống MEP xuyên sàn. | D14: Bằng mắt thường. | E14: Biên bản nghiệm thu định vị và cố định ống MEP xuyên sàn.
C15: Đục tẩy vệ sinh cổ ống, ghép ván khuôn, quấn băng trương nở, tưới bám dính đổ bù sika hoặc vật liệu khác theo BPTC được duyệt. | D15: Bằng mắt thường. | E15: - Đục vát 60 độ bê tông quanh cổ ống.
C16: Quyét chống thấm | D16: Bằng mắt thường. Định mức theo quy định của loại vật liệu chống thấm phê duyệt. | E16: Quét 02 lớp chống thấm, lớp thứ 2 vuông góc với lớp thứ nhất, quét vén lên chân tường 30cm, đảm bảo vật liệu phủ kín bề mặt nền chống thấm. | H16: TCVN 367-2006
C17: Ngâm nước kiểm tra thấm nền. | D17: Bằng mắt thường. | E17: Bơm ngâm nước tối thiểu 24h để kiểm tra xác nhận công tác chống thấm hoàn tất. | H17: TCVN 367-2006
C18: Nghiệm thu công tác chống thấm. | D18: - Chứng chỉ vật liệu và kết quả thí nghiệm vật liệu đầu vào. - Biên bản nghiệm thu vật liệu chống thấm. - Bản vẽ Shopdrawing - Checklist kiểm tra quá trình thi công. | E18: - Sau 2-3 ngày ngâm nước, kiểm tra toàn bộ bề mặt nền chống thấm nếu không có nước rò rỉ hoặc ẩm ướt thì xác nhận công tác chống thấm hoàn thành. | H18: TCVN 367-2006
B19: Ghi chú: Chi tiết các chỉ tiêu xem tiêu chuẩn kỹ thuật quy định tại cột ghi chú
A20: GHI CHÚ CHUNG:
A33: CHỦ ĐẦU TƯ TRỢ LÝ XÂY NHÀ ĐƠN VỊ THI CÔNG

Sheet BM30
A2: CÔNG TY TNHH THƯƠNG MẠI VÀ DỊCH VỤ XÂY DỰNG NHÀ CỦA MÌNH AC | E2: CỘNG HÒA XÃ HỘI CHỦ NGHĨA VIỆT NAM
E3: Độc Lập - Tự Do - Hạnh Phúc
E4: Ngày…..tháng…..năm 202…..
A5: CHECKLIST KIỂM TRA | I5: Ấn để trở về sheet " Danh mục"
A6: Công trình: | C6: =+'DANH MỤC'!A2 -> Công trình:
C7: =+'DANH MỤC'!A3 -> Địa điểm:
C8: ="Công tác"&": "&'DANH MỤC'!B41 -> Công tác: Láng nền sàn
A10: TT | B10: Công tác | C10: Công việc kiểm tra: | D10: Phương pháp kiểm tra | E10: Mức cho phép | F10: Đánh giá | H10: Ghi chú
F11: Đạt | G11: K.Đạt
B12: Công tác Láng nền | C12: Kiểm tra cấp phối vữa lát nền | D12: Bằng mắt thường Lấy mẫu thí nghiệm | E12: Kết quả mẫu thí nghiệm
C13: Kiểm tra vệ sinh, tạo nhám bề mặt; xử lý khuyết tật bề mặt nền… | D13: Bằng mắt thường. | E13: BPTC láng nền được phê duyệt.
C14: Kiểm tra đắp mốc (khoảng cách, cao độ mốc…) | D14: Bằng mắt thường. Đo bằng thước | H14: TCVN 9377-2012
C15: Kiểm tra tưới hồ dầu trước khi láng | D15: Bằng mắt thường. | E15: BPTC láng nền được phê duyệt.
C16: Kiểm tra tình trạng chất lượng vữa trong quá trình thi công | D16: Lấy mẫu thí nghiệm | E16: BPTC láng nền được phê duyệt.
C17: Công tác bảo dưỡng lớp cán nền | D17: Bằng mắt thường. | E17: - Sau 12h tiến hành tưới nước bảo dưỡng bề mặt trong vòng 05 ngày. | H17: TCVN 9377-2012
C18: Kiểm tra chất lượng sau khi cán: - Kiểm tra cao độ, độ phẳng (lỗi/lõm), độ dốc.. - Kiểm tra gõ ộp, độ đặc chắc, bề mặt | D18: Thước tầm, bi gõ ộp | H18: TCVN 9377-2012
C19: Công tác sửa chữa khuyết tật và vệ sinh | D19: Bằng mắt thường | E19: BPTC láng nền được phê duyệt.
B20: Ghi chú: Chi tiết các chỉ tiêu xem tiêu chuẩn kỹ thuật quy định tại cột ghi chú
A21: GHI CHÚ CHUNG:
A34: CHỦ ĐẦU TƯ TRỢ LÝ XÂY NHÀ ĐƠN VỊ THI CÔNG

Sheet BM31
A2: CÔNG TY TNHH THƯƠNG MẠI VÀ DỊCH VỤ XÂY DỰNG NHÀ CỦA MÌNH AC | E2: CỘNG HÒA XÃ HỘI CHỦ NGHĨA VIỆT NAM
E3: Độc Lập - Tự Do - Hạnh Phúc
E4: Ngày…..tháng…..năm 202…..
A5: CHECKLIST KIỂM TRA | I5: Ấn để trở về sheet " Danh mục"
A6: Công trình: | C6: =+'DANH MỤC'!A2 -> Công trình:
C7: =+'DANH MỤC'!A3 -> Địa điểm:
C8: ="Công tác"&": "&'DANH MỤC'!B42 -> Công tác: Ốp gạch
A10: TT | B10: Công tác | C10: Công việc kiểm tra: | D10: Phương pháp kiểm tra | E10: Mức cho phép | F10: Đánh giá | H10: Ghi chú
F11: Đạt | G11: K.Đạt
B12: Công tác ốp gạch | C12: Kiểm tra chủng loại, chất lượng, vật liệu gạch ốp ( Xi măng, keo, cấp phối vữa…) | D12: Bằng mắt thường Chứng nhận chất lượng Phiếu xuất kho. | E12: Kiểm tra theo mẫu gạch được phê duyệt
C13: - Bề mặt tường, trát lót đã được nghiệm thu và vệ sinh. - Kiểm tra chia ô lưới và vị trí viên gạch mốc ốp đầu tiên. - Tạo ẩm liên kết bề mặt tường với gạch. - Ngâm nước gạch trước khi ốp. | D13: Bằng mắt thường. | E13: Biên bản nghiệm thu tường, trát lót, thiết bị lắp đặt âm tường. Bản vẽ Shopdrawing được phê duyệt.
C14: Kiểm tra quá trình ốp tường | D14: Bằng mắt thường. Thước tầm dài 2,5m. Thước ni vô Máy laser | E14: - Dùng bay răng cưa để trải keo, hồ dầu lên bề mặt tường, gạch. - Dùng búa cao su để gõ tăng liên kết giữa gạch với tường. - Dùng thước ni vô kiểm tra độ phẳng mặt ốp. - Lắp ke nhựa tại các vị trí góc viên gạch ốp.
C15: Kiểm tra mạch: Kiểm tra sai lệch theo phương đứng, phương ngang, sắc nét, đồng đều. | D15: Bằng mắt thường. | H15: TCVN 9377-2012
C16: Kiểm tra độ thẳng góc hàng gạch ốp chân tường. | D16: Ke góc vuông | E16: BPTC ốp gạch được phê duyệt
C17: Kiểm tra mạch gạch vị trí giao tường ốp với gạch lát nền vệ sinh vát nghiêng 45 độ, thẳng đều sắc nét. | D17: Bằng mắt thường. | E17: Biện pháp thi công ốp gạch
C18: Kiểm tra mặt phẳng ốp, cao độ dừng ốp | D18: Thước tầm, Máy laser | E18: Kiểm tra bằng thước dài 2m đặt áp sát vào mặt ốp không quá 2mm. Độ không bằng phẳng theo hai phương : 2mm | H18: TCVN 9377-2012
C19: - Kiểm tra liên kết giữa gạch và tường, kiểm tra bộp | D19: Thước tầm, bi gõ ộp | E19: Gõ lên bề mặt ốp không có tiếng bộp. | H19: TCVN 9377-2012
