Workbook

Sheet Tổng hợp_PA Full
A1: KHAI TOÁN NGÂN SÁCH XÂY NHÀ_PA FULL
A2: KHAI TOÁN NGÂN SÁCH XÂY NHÀ | F2: =F51 -> 7931400823
A3: Trong đó
A4: STT | B4: Hạng mục | C4: Diện tích | E4: Đơn giá | F4: Thành iền
A5: 1 | B5: M2 xây dựng phần thô | C5: ='m2 xây dựng_PA Full'!D15 -> 810.55 | E5: 3900000 | F5: =C5*E5 -> 3161145000
A6: 2 | B6: M2 phần hoàn thiện | C6: ='m2 xây dựng_PA Full'!F15 -> 647.25 | E6: 3200000 | F6: =C6*E6 -> 2071200000
A7: 3 | B7: M2 hoàn thiện giai đoạn 2 | C7: 115.5 | E7: 5100000 | F7: =C7*E7 -> 589050000
A8: 4 | B8: Chi phí khác | F8: =F2-F5-F6-F7 -> 2110005823
A10: BẢNG CHI TIẾT CÁC HẠNG MỤC
A11: STT | B11: Các loại chi phí | C11: ĐVT | D11: Số lượng | E11: Đơn giá | F11: Thành tiền | G11: Ghi chú
A12: 1 | B12: Mua đất | C12: Lô đất | F12: =D12*E12 -> 0
A13: 2 | B13: Tháo dỡ nhà cũ | C13: Gói | F13: =D13*E13 -> 0
A14: 3 | B14: Định vị ranh đất | C14: Gói | D14: 1 | E14: 5000000 | F14: =E14*D14 -> 5000000
A15: 4 | B15: Xin phép xây dựng | C15: Hồ sơ | F15: =D15*E15 -> 0
A16: 5 | B16: Thuê nhà tạm thời | C16: Tháng | E16: 15000000 | F16: =D16*E16 -> 0
A17: 6 | B17: Tư vấn đầu tư | C17: Gói
A18: 7 | B18: Di dời đồng hồ điện nước, đấu nối hố ga | C18: Lần
A19: 8 | B19: Thiết kế xây dựng | C19: m2 | D19: =C6 -> 647.25 | E19: 180000 | F19: =E19*D19 -> 116505000
A20: 9 | B20: Thẩm tra hồ sơ và Kiểm định (nếu có) | C20: Lần | F20: =D20*E20 -> 0
A21: 10 | B21: Lập dự toán | C21: Gói | D21: 1 | F21: =D21*E21 -> 0
A22: 11 | B22: Bảo hiểm công trình xây dựng | C22: % công trình | D22: 0.0005 | E22: =F30 -> 3161145000 | F22: =D22*E22 -> 1580572.5 | G22: Chủ nhà mua
A23: 12 | B23: Hoạt động tâm linh (khởi công, xin phép) | C23: Lần
A24: 13 | B24: Thuê bảo vệ, người nhà trông coi | C24: Tháng | D24: 2 | F24: =D24*E24 -> 0 | G24: Bảo quản đồ nội thất, thiết bị 2 tháng cuối công trình
A25: 14 | B25: Khảo sát địa chất | C25: Vị trí | D25: 2
A26: 15 | B26: Khoan dẫn (tạo lỗ ép cọc) | C26: md
A27: 16 | B27: Ép cọc | C27: md | D27: =48*10 -> 480 | E27: 275000 | F27: =D27*E27 -> 132000000 | G27: 48 tim, 10m/tim (tạm tính)
A28: 17 | B28: Nhân công ép cọc | C28: Tim | D28: 49 | E28: 900000 | F28: =D28*E28 -> 44100000
A29: 18 | B29: Ép cừ C chống sạt lở | C29: md | D29: 30 | E29: 2400000 | F29: =D29*E29 -> 72000000 | G29: 2 hệ giằng tường vây
A30: 19 | B30: Xây dựng phần thô | C30: m2 | D30: =C5 -> 810.55 | E30: =E5 -> 3900000 | F30: =D30*E30 -> 3161145000 | G30: Vật tư phần thô nhân công hoàn thiện
A31: 20 | B31: Hoàn thiện | C31: m2 | D31: =C6 -> 647.25 | E31: =E6 -> 3200000 | F31: =D31*E31 -> 2071200000 | G31: Đơn giá sẽ cập nhật sau khi nhận bản vẽ đầy đủ
A32: 22 | B32: Nội thất | C32: phòng | D32: 20 | E32: 40000000 | F32: =D32*E32 -> 800000000 | G32: Tạm tính nội thất 1 phòng (bao gồm nội thất gỗ, thiết bị)
A33: 23 | B33: Thang máy | C33: Bộ | D33: 1 | E33: =320000000+(10000000*2) -> 340000000 | F33: =D33*E33 -> 340000000 | G33: Thang máy 6 điểm dừng Bộ tiêu chuẩn 320tr 4 điểm dừng Thêm 1 điểm dừng tăng 10tr
A34: 24 | B34: Điểm dừng thang máy | C34: Điểm | D34: 6 | E34: 15000000 | F34: =D34*E34 -> 90000000
A35: 25 | B35: Dây điện 3P thang máy | C35: Gói | D35: 1 | E35: 15000000 | F35: =E35*D35 -> 15000000
A36: 26 | B36: Phòng cháy chữa cháy | C36: Gói | D36: 1 | E36: 450000000 | F36: =E36*D36 -> 450000000
A37: 27 | B37: Trợ Lý Xây Nhà | C37: Tháng | D37: 7 | E37: 23980000 | F37: =D37*E37 -> 167860000
A38: 28 | B38: Công nghệ thông minh và an ninh | C38: Gói | D38: 1 | F38: =D38*E38 -> 0
A39: 29 | B39: Vườn và cảnh quan | C39: Gói | D39: 1 | F39: =D39*E39 -> 0
A40: 30 | B40: Quà cáp hàng xóm, bồi dưỡng abc, thợ thuyền | C40: Lần | D40: 10 | E40: 2000000 | F40: =D40*E40 -> 20000000
A41: 31 | B41: Hoạt động tâm linh (bồi hoàn long mạch, cất nóc) | C41: Lần | F41: =D41*E41 -> 0
...

Sheet m2 xây dựng_PA Full
A1: STT | B1: HẠNG MỤC | C1: KHỐI LƯỢNG (m2) | D1: HỆ SỐ | E1: DIỆN TÍCH PHẦN THÔ (m2) | F1: HỆ SỐ | G1: DIỆN TÍCH HOÀN THIỆN (m2) | H1: HỆ SỐ | I1: DIỆN TÍCH THIẾT KẾ (m2)
A2: 1 | B2: Móng | C2: 128 | D2: 0.5 | E2: =C2*D2 -> 64
A3: 2 | B3: Tầng hầm sau nhà | C3: =C4/2 -> 55 | D3: 2 | E3: =C3*D3 -> 110 | F3: 0.7 | G3: =C3*F3 -> 38.5
A4: 3 | B4: Trệt | C4: 110 | D4: 1 | E4: =C4*D4 -> 110 | F4: 1 | G4: =C4*F4 -> 110
A5: 4 | B5: Lửng | C5: =C4*0.65 -> 71.5 | D5: 1 | E5: =C5*D5 -> 71.5 | F5: 1 | G5: =C5*F5 -> 71.5
A6: 5 | B6: Thông tầng tầng lửng | C6: =C4-C5 -> 38.5 | D6: 0.5 | E6: =C6*D6 -> 19.25 | F6: 0.5 | G6: =C6*F6 -> 19.25
A7: 6 | B7: Lầu 1 | C7: =C4 -> 110 | D7: 1 | E7: =C7*D7 -> 110 | F7: 1 | G7: =C7*F7 -> 110
A8: 7 | B8: Lầu 2 | C8: =C7 -> 110 | D8: 1 | E8: =C8*D8 -> 110 | F8: 1 | G8: =C8*F8 -> 110
A9: 8 | B9: Lầu 3 | C9: =C8 -> 110 | D9: 1 | E9: =C9*D9 -> 110 | F9: 1 | G9: =C9*F9 -> 110
A10: 9 | B10: Sân thượng có mái che | C10: =C9*0.3 -> 33 | D10: 1 | E10: =C10*D10 -> 33 | F10: 1 | G10: =C10*F10 -> 33
A11: 10 | B11: Sân thượng không mái che | C11: =C9-C10 -> 77 | D11: 0.5 | E11: =C11*D11 -> 38.5 | F11: 0.3 | G11: =C11*F11 -> 23.1
A12: 11 | B12: Mái | C12: =C10 -> 33 | D12: 0.5 | E12: =C12*D12 -> 16.5 | F12: 0.5 | G12: =C12*F12 -> 16.5
A13: 13 | B13: Sân sau | C13: =C2-C4 -> 18 | D13: 0.5 | E13: =C13*D13 -> 9 | F13: 0.3 | G13: =C13*F13 -> 5.4
A14: 14 | B14: Hố pít thang máy | C14: =2*2.2 -> 4.4 | D14: 2 | E14: =C14*D14 -> 8.8
A15: Tổng cộng | D15: =SUM(E2:E14) -> 810.55 | F15: =SUM(G2:G14) -> 647.25 | H15: =SUM(I2:I12) -> 0

Sheet Tổng hợp_PA 2 lầu
A1: KHAI TOÁN NGÂN SÁCH XÂY NHÀ_PA 2 LẦU
A2: KHAI TOÁN NGÂN SÁCH XÂY NHÀ | F2: =F53 -> 6083020873
A3: Trong đó
A4: STT | B4: Hạng mục | C4: Diện tích | E4: Đơn giá | F4: Thành iền
A5: 1 | B5: M2 xây dựng phần thô | C5: ='m2 xây dựng_PA 2 lầu'!D11 -> 579.55 | E5: 3900000 | F5: =C5*E5 -> 2260245000
A6: 2 | B6: M2 phần hoàn thiện | C6: ='m2 xây dựng_PA 2 lầu'!F11 -> 481.15 | E6: 3200000 | F6: =C6*E6 -> 1539680000
A7: 3 | B7: M2 hoàn thiện giai đoạn 2 | C7: ='m2 xây dựng_PA 2 lầu'!C5 -> 38.5 | E7: 5100000 | F7: =C7*E7 -> 196350000
A8: 4 | B8: Chi phí khác | F8: =F2-F5-F6-F7 -> 2086745873
A10: BẢNG CHI TIẾT CÁC HẠNG MỤC
A11: STT | B11: Các loại chi phí | C11: ĐVT | D11: Số lượng | E11: Đơn giá | F11: Thành tiền | G11: Ghi chú
A12: 1 | B12: Mua đất | C12: Lô đất | F12: =D12*E12 -> 0
A13: 2 | B13: Tháo dỡ nhà cũ | C13: Gói | F13: =D13*E13 -> 0
A14: 3 | B14: Định vị ranh đất | C14: Gói | D14: 1 | E14: 5000000 | F14: =E14*D14 -> 5000000
A15: 4 | B15: Xin phép xây dựng | C15: Hồ sơ | F15: =D15*E15 -> 0
A16: 5 | B16: Thuê nhà tạm thời | C16: Tháng | E16: 15000000 | F16: =D16*E16 -> 0
A17: 6 | B17: Tư vấn đầu tư | C17: Gói
A18: 7 | B18: Di dời đồng hồ điện nước, đấu nối hố ga | C18: Lần
A19: 8 | B19: Thiết kế xây dựng | C19: m2 | D19: =C6 -> 481.15 | E19: 180000 | F19: =E19*D19 -> 86607000
A20: 9 | B20: Thẩm tra hồ sơ và Kiểm định (nếu có) | C20: Lần | F20: =D20*E20 -> 0
A21: 10 | B21: Lập dự toán | C21: Gói | D21: 1 | F21: =D21*E21 -> 0
A22: 11 | B22: Bảo hiểm công trình xây dựng | C22: % công trình | D22: 0.0005 | E22: =F30 -> 2260245000 | F22: =D22*E22 -> 1130122.5 | G22: Chủ nhà mua
A23: 12 | B23: Hoạt động tâm linh (khởi công, xin phép) | C23: Lần
A24: 13 | B24: Thuê bảo vệ, người nhà trông coi | C24: Tháng | D24: 2 | F24: =D24*E24 -> 0 | G24: Bảo quản đồ nội thất, thiết bị 2 tháng cuối công trình
A25: 14 | B25: Khảo sát địa chất | C25: Vị trí | D25: 2
A26: 15 | B26: Khoan dẫn (tạo lỗ ép cọc) | C26: md
A27: 16 | B27: Ép cọc | C27: md | D27: =48*10 -> 480 | E27: 275000 | F27: =D27*E27 -> 132000000 | G27: 48 tim, 10m/tim (tạm tính)
A28: 17 | B28: Nhân công ép cọc | C28: Tim | D28: 48 | E28: 900000 | F28: =D28*E28 -> 43200000
A29: 18 | B29: Ép cừ C chống sạt lở | C29: md | E29: 2400000 | F29: =D29*E29 -> 0 | G29: 2 hệ giằng tường vây
A30: 19 | B30: Xây dựng phần thô | C30: m2 | D30: =C5 -> 579.55 | E30: =E5 -> 3900000 | F30: =D30*E30 -> 2260245000 | G30: Vật tư phần thô nhân công hoàn thiện
A31: 20 | B31: Hoàn thiện giai đoạn 1 (trước hoàn công) | C31: m2 | D31: =C6 -> 481.15 | E31: =E6 -> 3200000 | F31: =D31*E31 -> 1539680000 | G31: Đơn giá sẽ cập nhật sau khi nhận bản vẽ đầy đủ
A32: 21 | B32: Hoàn thiện giai đoạn 2 (sau hoàn công) | C32: m2 | D32: =C7 -> 38.5 | E32: =E7 -> 5100000 | F32: =D32*E32 -> 196350000 | G32: Tầng lửng
A33: 22 | B33: Nội thất | C33: phòng | D33: 12 | E33: 40000000 | F33: =D33*E33 -> 480000000 | G33: Tạm tính nội thất 1 phòng (bao gồm nội thất gỗ, thiết bị)
A34: 23 | B34: Thang máy | C34: Bộ | D34: 1 | E34: =320000000 -> 320000000 | F34: =D34*E34 -> 320000000 | G34: Thang máy 6 điểm dừng Bộ tiêu chuẩn 320tr 4 điểm dừng Thêm 1 điểm dừng tăng 10tr
A35: 24 | B35: Điểm dừng thang máy | C35: Điểm | D35: 4 | E35: 15000000 | F35: =D35*E35 -> 60000000
A36: 25 | B36: Dây điện 3P thang máy | C36: Gói | D36: 1 | E36: 15000000 | F36: =E36*D36 -> 15000000
A37: 26 | B37: Phòng cháy chữa cháy | C37: Gói | D37: 1 | E37: 450000000 | F37: =E37*D37 -> 450000000
A38: 27 | B38: Trợ Lý Xây Nhà | C38: Tháng | D38: 5 | E38: 23980000 | F38: =D38*E38 -> 119900000
A39: 28 | B39: Công nghệ thông minh và an ninh | C39: Gói | D39: 1 | F39: =D39*E39 -> 0
A40: 29 | B40: Vườn và cảnh quan | C40: Gói | D40: 1 | F40: =D40*E40 -> 0
A41: 30 | B41: Quà cáp hàng xóm, bồi dưỡng abc, thợ thuyền | C41: Lần | D41: 6 | E41: 2000000 | F41: =D41*E41 -> 12000000
...

Sheet m2 xây dựng_PA 2 lầu
A1: STT | B1: HẠNG MỤC | C1: KHỐI LƯỢNG (m2) | D1: HỆ SỐ | E1: DIỆN TÍCH PHẦN THÔ (m2) | F1: HỆ SỐ | G1: DIỆN TÍCH HOÀN THIỆN (m2) | H1: HỆ SỐ | I1: DIỆN TÍCH THIẾT KẾ (m2)
A2: 1 | B2: Móng | C2: 128 | D2: 0.5 | E2: =C2*D2 -> 64
A3: 2 | B3: Trệt | C3: 110 | D3: 1 | E3: =C3*D3 -> 110 | F3: 1 | G3: =C3*F3 -> 110
A4: 3 | B4: Lửng | C4: =C3*0.65 -> 71.5 | D4: 1 | E4: =C4*D4 -> 71.5 | F4: 1 | G4: =C4*F4 -> 71.5
A5: 4 | B5: Thông tầng tầng lửng | C5: =C3-C4 -> 38.5 | D5: 0.5 | E5: =C5*D5 -> 19.25 | F5: 0.5 | G5: =C5*F5 -> 19.25
A6: 5 | B6: Lầu 1 | C6: =C3 -> 110 | D6: 1 | E6: =C6*D6 -> 110 | F6: 1 | G6: =C6*F6 -> 110
A7: 6 | B7: Lầu 2 | C7: =C6 -> 110 | D7: 1 | E7: =C7*D7 -> 110 | F7: 1 | G7: =C7*F7 -> 110
A8: 7 | B8: Mái BTCT | C8: =C7 -> 110 | D8: 0.7 | E8: =C8*D8 -> 77 | F8: 0.5 | G8: =C8*F8 -> 55
A9: 8 | B9: Sân sau | C9: =C2-C3 -> 18 | D9: 0.5 | E9: =C9*D9 -> 9 | F9: 0.3 | G9: =C9*F9 -> 5.4
A10: 9 | B10: Hố pít thang máy | C10: =2*2.2 -> 4.4 | D10: 2 | E10: =C10*D10 -> 8.8
A11: Tổng cộng | D11: =SUM(E2:E10) -> 579.55 | F11: =SUM(G2:G10) -> 481.15 | H11: =SUM(I2:I8) -> 0
E12: 7000000
E13: =D11*E12 -> 4056850000
